Workbook

Sheet README
A2: SN | B2: Particulars | C2: Remarks
A3: 1 | B3: Deferred Tax Working + Effective Tax Reconciliation
A4: 2 | B4: Inter Company Loan Outstanding Balance Current Year and PY - Please reconcile once. We believe there is some mismatch to the tune of INR 388000. | D4: Done

Sheet Input
B1: BVC Specialities Private Limited | C1: CIN : U24230GJ2021PTC123855 | E1: Decimal
B2: Rounding Off | C2: 100000 | D2: =IF(C2=100000,"(₹ in Lakh)","(₹ in '000)") -> (₹ in Lakh) | E2: 0
B4: Date - CY | C4: 31 March 2024 | D4: 1 April 2024 | E4: =UPPER(C4) -> 31 MARCH 2024 | F4: =UPPER(D4) -> 1 APRIL 2024 | H4: 2023-24
B5: Date - PY | C5: 31 March 2023 | D5: 1 April 2023 | E5: =UPPER(C5) -> 31 MARCH 2023 | F5: =UPPER(D5) -> 1 APRIL 2023 | H5: 2022-23
C6: 31 March 2022 | D6: 1 April 2022 | E6: =UPPER(C6) -> 31 MARCH 2022 | F6: =UPPER(D6) -> 1 APRIL 2022 | H6: 2021-22
C7: 31 March 2021
C8: 1 April 2021 | E8: =UPPER(C8) -> 1 APRIL 2021 | F8: 5 July 2021 | H8: 2020-21
C10: Corporate Information | D10: 1
C11: Significant Accounting Policies | D11: =D10+1 -> 2
B12: Non Current Assets
B13: (a) | C13: Property, Plant and Equipment | D13: =D11+1 -> 3
B14: (b) | C14: Right of Use Assets
B15: (c) | C15: Capital work-in-progress
B16: (d) | C16: Intangible Assets
B17: (e) | C17: Financial Assets
C18: Loans | D18: 5
C19: Other Financial Assets | D19: 6
B20: (f) | C20: Deferred Tax Assets (Net) | D20: =D13+1 -> 4
B21: (g) | C21: Other Non Current Assets | D21: =D20+1 -> 5
C22: Total Non Current Assets
B23: Current Assets
B24: (a) | C24: Inventories | D24: 7
B25: (a) | C25: Financial Assets
C26: Trade Receivables | D26: 8
C27: Cash and Cash Equivalents | D27: 9
C28: Other Bank Balance | D28: 10
C29: Loans
C30: Other Financial Assets
B31: (b) | C31: Other Current Assets | D31: 11
C32: Total Current Assets
C33: Total Assets
B34: EQUITY AND LIABILITIES
B35: Equity
B36: (a) | C36: Equity Share Capital | D36: 12
B37: (b) | C37: Other Equity | D37: 13
C38: Total Equity
B39: Liabilities
B40: Non Current Liabilities
B41: (a) | C41: Financial Liabilities
C42: Borrowings | D42: =D37+1 -> 14
...

Sheet Pivot
D3: Values
A4: Type | B4: Note | C4: Ind AS Head | D4: Sum of Current | E4: Sum of Non-Current | F4: Sum of Total
A5: Equity | B5: 13 | C5: Equity share capital | D5: 0 | E5: -1365970 | F5: -1365970
C6: Other equity | D6: 0 | E6: -1999973649 | F6: -1999973649 | I6: CY Profit
B7: 14 | C7: Other equity | D7: 0 | E7: -8.7918109e+08 | F7: -8.7918109e+08 | H7: =-823214.934735809*1000 -> -8.2321493e+08 | I7: =F7-H7 -> -55966159
A8: Equity Total | D8: 0 | E8: -2.8805207e+09 | F8: -2.8805207e+09
A9: Liabilities | B9: 4 | C9: Deferred Tax Liabilities (Net) | D9: -142606.21 | E9: 0 | F9: -142606.21
B10: 7 | C10: Other Tax Assets (Net) | D10: 0 | E10: 0 | F10: 0
B11: 15 | C11: Borrowings | D11: -2.4152271e+08 | E11: -2.6059553e+09 | F11: -2.8474781e+09
B12: 16 | C12: Provisions | D12: -388605 | E12: -1839333 | F12: -2227938
B13: 17 | C13: Trade payables | D13: -1.2661909e+08 | E13: 0 | F13: -1.2661909e+08
B14: 18 | C14: Other financial liabilities | D14: -1.4259158e+08 | E14: 0 | F14: -1.4259158e+08
B15: 19 | C15: Other Current Liabilities | D15: -5827827.9 | E15: 0 | F15: -5827827.9
A16: Liabilities Total | D16: -5.1709242e+08 | E16: -2.6077947e+09 | F16: -3.1248871e+09
A17: Asset | B17: 3 | C17: Property, Plant and Equipment | D17: 0 | E17: 5.3252185e+09 | F17: 5.3252185e+09
B18: 6 | C18: Other financial assets | D18: 0 | E18: 33715121 | F18: 33715121
B19: 7 | C19: Other Tax Assets (Net) | D19: 0 | E19: 1012555 | F19: 1012555
B20: 8 | C20: Non Current Assets | D20: 0 | E20: 0 | F20: 0
B21: 9 | C21: Inventories | D21: 45600578 | E21: 0 | F21: 45600578
B22: 10 | C22: Trade receivables | D22: 13928477 | E22: 0 | F22: 13928477
B23: 11 | C23: Cash & Cash Equivalents | D23: 8972905.8 | E23: 0 | F23: 8972905.8
B24: 12 | C24: Other Current Assets | D24: 5.2099744e+08 | E24: 0 | F24: 5.2099744e+08
A25: Asset Total | D25: 5.894994e+08 | E25: 5.3599461e+09 | F25: 5.9494455e+09
A26: Expenses | B26: 3 | C26: Depreciation and Amortisation Expense | D26: 0 | E26: 0 | F26: 51221254
B27: 22 | C27: Cost of material consumed | D27: 0 | E27: 0 | F27: 44815227
B28: 23 | C28: Changes in inventories of finished goods and work-in-progress | D28: 0 | E28: 0 | F28: -2769259.9
B29: 24 | C29: Employee benefits expense | D29: 0 | E29: 0 | F29: 7060372
B30: 25 | C30: Finance costs | D30: 0 | E30: 0 | F30: 14199565
B31: 26 | C31: Other expenses | D31: 0 | E31: 0 | F31: 14492003
B32: - | C32: Current income tax | D32: 0 | E32: 0 | F32: 1495489
C33: Tax Expense | D33: 0 | E33: 0 | F33: 0
A34: Expenses Total | D34: 0 | E34: 0 | F34: 1.3051465e+08
A35: Income | B35: 20 | C35: Other Income | D35: 0 | E35: 0 | F35: -67940.18
C36: Revenue from operations | D36: 0 | E36: 0 | F36: -68979137
B37: 21 | C37: Other Income | D37: 0 | E37: 0 | F37: -5505299.5
A38: Income Total | D38: 0 | E38: 0 | F38: -74552377 | I38: =F38+F34 -> 55962273 | J38: =-PL!D34*1000 -> 5945240 | K38: =I38-J38 -> 50017033
A39: Grand Total | D39: 72406975 | E39: -1.2836925e+08 | F39: -1.6385689e-05

Sheet Master Grouping
A1: Code | B1: INDAS Head | C1: INDAS Sub Head
A2: 10000000 | B2: Equity share capital | C2: =VLOOKUP(A2,'TB BVS 31.03.26'!B:E,4,0) -> 315,940 (previous year: 315,940) equity shares of Rs 10 each fully paid up
A3: 10000004 | B3: Equity share capital | C3: =VLOOKUP(A3,'TB BVS 31.03.26'!B:E,4,0) -> Pref Shar CCPS-BVCPL
A4: 10100000 | B4: Other equity | C4: =VLOOKUP(A4,'TB BVS 31.03.26'!B:E,4,0) -> Closing balance - Securities Premium
A5: 10100001 | B5: Other equity | C5: =VLOOKUP(A5,'TB BVS 31.03.26'!B:E,4,0) -> Closing balance - Retained Earnings
A6: 10100002 | B6: Other equity | C6: =VLOOKUP(A6,'TB BVS 31.03.26'!B:E,4,0) -> Closing balance - Retained Earnings
A7: 10100009 | B7: Other equity | C7: =VLOOKUP(A7,'TB BVS 31.03.26'!B:E,4,0) -> Closing balance - Retained Earnings
A8: 10200015 | B8: Borrowings | C8: =VLOOKUP(A8,'TB BVS 31.03.26'!B:E,4,0) -> Term Loan from Bank*
A9: 10200016 | B9: Borrowings | C9: =VLOOKUP(A9,'TB BVS 31.03.26'!B:E,4,0) -> Term Loan from Bank*
A10: 10200018 | B10: Borrowings | C10: =VLOOKUP(A10,'TB BVS 31.03.26'!B:E,4,0) -> Term Loan from Bank*
A11: 10300002 | B11: Borrowings | C11: =VLOOKUP(A11,'TB BVS 31.03.26'!B:E,4,0) -> Term Loan from Bank*
A12: 10400001 | B12: Deferred Tax Liabilities (Net) | C12: =VLOOKUP(A12,'TB BVS 31.03.26'!B:E,4,0) -> Deferred Tax
A13: 10500000 | B13: Provisions | C13: =VLOOKUP(A13,'TB BVS 31.03.26'!B:E,4,0) -> Provision for employee benefits - Gratuity
... A237: 10000001 | B237: Equity share capital | C237: =VLOOKUP(A237,'TB BVS 31.03.26'!B:E,4,0) -> #N/A

Sheet TB BVS 31.3.25
G1: BS | H1: CFS
G2: =BS!G61 -> 0.54886832 | H2: =#REF! -> #REF!
A3: =Input!B1 -> BVC Specialities Private Limited | G3: 0
A4: Trial Balance as on 31 March 2024 | G4: =SUBTOTAL(9,G7:G1096) -> 1.5739688e+10 | H4: =SUBTOTAL(9,H7:H1096) -> -1.5739688e+10 | I4: =SUBTOTAL(9,I7:I1096) -> 2.1457672e-06 | J4: =SUBTOTAL(9,J7:J1096) -> -1.009453e+08 | K4: =SUBTOTAL(9,K7:K1096) -> -95868897 | L4: =SUBTOTAL(9,L7:L115) -> 0
C5: Ind AS
A6: Type | B6: Code No. | C6: Note | D6: Ind AS Head | E6: Ind AS Sub Head | F6: Particulars | G6: Debit | H6: Credit | I6: Total | J6: Current | K6: Non-Current | L6: Check
A7: Equity | B7: 10000000 | C7: 13 | D7: Equity share capital | E7: 315,940 (previous year: 315,940) equity shares of Rs 10 each fully paid up | F7: Equity Share Capital | G7: 0 | H7: -1365970 | I7: =G7+H7 -> -1365970 | J7: 0 | K7: =I7-J7 -> -1365970 | L7: =I7-J7-K7 -> 0
A8: Equity | B8: 10000004 | C8: 13 | D8: Equity share capital | E8: Pref Shar CCPS-BVCPL | F8: 0.01% Non-Cumulative CCPS | G8: 0 | H8: -868680 | I8: =G8+H8 -> -868680 | J8: 0 | K8: =I8-J8 -> -868680 | L8: =I8-J8-K8 -> 0
A9: Equity | B9: 10100000 | C9: 14 | D9: Other equity | E9: Closing balance - Securities Premium | F9: Security Premium Account | G9: 0 | H9: -2.8885604e+09 | I9: =G9+H9 -> -2.8885604e+09 | J9: 0 | K9: =I9-J9 -> -2.8885604e+09 | L9: =I9-J9-K9 -> 0 | P9: Opening | Q9: CY | R9: Closing
A10: Equity | B10: 10100001 | C10: 14 | D10: Other equity | E10: Closing balance - Retained Earnings | F10: Retained earnings | G10: 2371971.4 | H10: 0 | I10: =G10+H10 -> 2371971.4 | J10: 0 | K10: =I10-J10 -> 2371971.4 | L10: =I10-J10-K10 -> 0 | P10: =-'BS Notes 3-18'!H243*1000 -> 2029035.2 | Q10: 386615.03 | R10: =SUBTOTAL(9,P10:Q10) -> 2415650.2
A11: Equity | B11: 10100002 | C11: 14 | D11: Other equity | E11: Closing balance - Retained Earnings | F11: Profit & Loss Account | G11: 7941080.5 | H11: 0 | I11: =G11+H11 -> 7941080.5 | J11: 0 | K11: =I11-J11 -> 7941080.5 | L11: =I11-J11-K11 -> 0 | P11: =I11 -> 7941080.5 | R11: =SUBTOTAL(9,P11:Q11) -> 7941080.5
A12: Equity | B12: 10100009 | C12: 14 | D12: Other equity | E12: Closing balance - Retained Earnings | F12: IND AS - Opening Balance - Retained Earnings | G12: 0 | H12: -38668.9 | I12: =G12+H12 -> -38668.9 | J12: 0 | K12: =I12-J12 -> -38668.9 | L12: =I12-J12-K12 -> 0
A13: Liabilities | B13: 10200015 | C13: 15 | D13: Borrowings | E13: Term Loan from Bank | F13: IND AS - Transaction Cost Impact on TL | G13: 1284522.4 | H13: 0 | I13: =G13+H13 -> 1284522.4 | J13: 0 | K13: =I13-J13 -> 1284522.4 | L13: =I13-J13-K13 -> 0 | P13: =I13 -> 1284522.4 | R13: =SUBTOTAL(9,P13:Q13) -> 1284522.4
A14: Liabilities | B14: 10200016 | C14: 15 | D14: Borrowings | E14: Term Loan from Bank | F14: TL_AXIS_ 923060053143888 | G14: 0 | H14: -2000000000 | I14: =G14+H14 -> -2000000000 | J14: -233100000 | K14: =I14-J14 -> -1766900000 | L14: =I14-J14-K14 -> 0
A15: Liabilities | B15: 10200018 | C15: 15 | D15: Borrowings | E15: Term Loan from Bank | F15: TL_AXIS_924060051723539 | G15: 0 | H15: -400000000 | I15: =G15+H15 -> -400000000 | J15: -46900000 | K15: =I15-J15 -> -353100000 | L15: =I15-J15-K15 -> 0
A16: Liabilities | B16: 10300002 | C16: 15 | D16: Borrowings | E16: Term Loan from Bank | F16: TL_HDFC_02400930000746 | G16: 0 | H16: -2.474626e+08 | I16: =G16+H16 -> -2.474626e+08 | J16: -30932825 | K16: =I16-J16 -> -2.1652978e+08 | L16: =I16-J16-K16 -> 0
A17: Liabilities | B17: 10400001 | C17: 4 | D17: Deferred Tax Liabilities (Net) | E17: Deferred Tax | F17: IND AS - Deferred Tax Liability | G17: 0 | H17: -238523.49 | I17: =G17+H17 -> -238523.49 | J17: =I17 -> -238523.49 | K17: =I17-J17 -> 0 | L17: =I17-J17-K17 -> 0
A18: Liabilities | B18: 10500000 | C18: 16 | D18: Provisions | E18: Provision for employee benefits - Gratuity | F18: Provision for Gratuity | G18: 0 | H18: -1940219 | I18: =G18+H18 -> -1940219 | J18: -198583 | K18: =I18-J18 -> -1741636 | L18: =I18-J18-K18 -> 0
A19: Liabilities | B19: 10500001 | C19: 16 | D19: Provisions | E19: Provision for compensated absences | F19: Provision for Leave Salary | G19: 0 | H19: -2662538 | I19: =G19+H19 -> -2662538 | J19: -506035 | K19: =I19-J19 -> -2156503 | L19: =I19-J19-K19 -> 0
A20: Liabilities | B20: 10600010 | C20: 15 | D20: Borrowings | E20: Unsecured loan from related parties | F20: Best Value Chem Pvt Ltd. | G20: 0 | H20: -2.6596834e+08 | I20: =G20+H20 -> -2.6596834e+08 | J20: 0 | K20: =I20-J20 -> -2.6596834e+08 | L20: =I20-J20-K20 -> 0
A21: Liabilities | B21: 10800000 | C21: 17 | D21: Trade payables | E21: Total outstanding dues of creditors other than micro enterprises and small enterprises | F21: Payable - Raw Material Import | G21: 0 | H21: -23799281 | I21: =G21+H21 -> -23799281 | J21: =I21 -> -23799281 | K21: =I21-J21 -> 0 | L21: =I21-J21-K21 -> 0
A22: Liabilities | B22: 10800001 | C22: 17 | D22: Trade payables | E22: Total outstanding dues of creditors other than micro enterprises and small enterprises | F22: Payable - Raw Material Domestic | G22: 0 | H22: -53207756 | I22: =G22+H22 -> -53207756 | J22: =I22 -> -53207756 | K22: =I22-J22 -> 0 | L22: =I22-J22-K22 -> 0
A23: Liabilities | B23: 10800002 | C23: 17 | D23: Trade payables | E23: Total outstanding dues of creditors other than micro enterprises and small enterprises | F23: Payable - Packing Material | G23: 0 | H23: -6382962 | I23: =G23+H23 -> -6382962 | J23: =I23 -> -6382962 | K23: =I23-J23 -> 0 | L23: =I23-J23-K23 -> 0
A24: Liabilities | B24: 10800003 | C24: 17 | D24: Trade payables | E24: Total outstanding dues of creditors other than micro enterprises and small enterprises | F24: Payable - Fuel | G24: 0 | H24: -7927826 | I24: =G24+H24 -> -7927826 | J24: =I24 -> -7927826 | K24: =I24-J24 -> 0 | L24: =I24-J24-K24 -> 0
A25: Liabilities | B25: 10800004 | C25: 17 | D25: Trade payables | E25: Total outstanding dues of creditors other than micro enterprises and small enterprises | F25: Payable - Others | G25: 0 | H25: -1.6782554e+08 | I25: =G25+H25 -> -1.6782554e+08 | J25: =I25 -> -1.6782554e+08 | K25: =I25-J25 -> 0 | L25: =I25-J25-K25 -> 0
A26: Liabilities | B26: 10800005 | C26: 18 | D26: Other financial liabilities | E26: Employee benefits payable | F26: Payables - Employees | G26: 0 | H26: -78704.78 | I26: =G26+H26 -> -78704.78 | J26: =I26 -> -78704.78 | K26: =I26-J26 -> 0 | L26: =I26-J26-K26 -> 0
A27: Liabilities | B27: 10900000 | C27: 17 | D27: Trade payables | E27: Total outstanding dues of creditors other than micro enterprises and small enterprises | F27: Provision_Other Expenses | G27: 0 | H27: -48270630 | I27: =G27+H27 -> -48270630 | J27: =I27 -> -48270630 | K27: =I27-J27 -> 0 | L27: =I27-J27-K27 -> 0
A28: Liabilities | B28: 20100001 | C28: 17 | D28: Trade payables | E28: Total outstanding dues of creditors other than micro enterprises and small enterprises | F28: Capital Advances | G28: 11010528 | H28: 0 | I28: =G28+H28 -> 11010528 | J28: =I28 -> 11010528 | K28: =I28-J28 -> 0 | L28: =I28-J28-K28 -> 0
A29: Liabilities | B29: 10900003 | C29: 18 | D29: Other financial liabilities | E29: Employee benefits payable | F29: Provision_PF and ESIC Contribution by Company | G29: 0 | H29: -311807 | I29: =G29+H29 -> -311807 | J29: =I29 -> -311807
A30: Liabilities | B30: 10900018 | C30: 18 | D30: Other financial liabilities | E30: Employee benefits payable | F30: Salary Payable | G30: 0 | H30: -6010926 | I30: =G30+H30 -> -6010926 | J30: =I30 -> -6010926 | K30: =I30-J30 -> 0 | L30: =I30-J30-K30 -> 0
A31: Liabilities | B31: 11000001 | C31: 19 | D31: Other Current Liabilities | E31: Statutory liabilities | F31: TDS_Professional and Consulting_194J | G31: 0 | H31: -604915.06 | I31: =G31+H31 -> -604915.06 | J31: =I31 -> -604915.06 | K31: =I31-J31 -> 0 | L31: =I31-J31-K31 -> 0
A32: Liabilities | B32: 11000002 | C32: 19 | D32: Other Current Liabilities | E32: Statutory liabilities | F32: TDS_Contractors_194C | G32: 0 | H32: -1218102.8 | I32: =G32+H32 -> -1218102.8 | J32: =I32 -> -1218102.8 | K32: =I32-J32 -> 0 | L32: =I32-J32-K32 -> 0
A33: Liabilities | B33: 11000003 | C33: 19 | D33: Other Current Liabilities | E33: Statutory liabilities | F33: TDS_Interest on borrowing_194A | G33: 0 | H33: -995290.17 | I33: =G33+H33 -> -995290.17 | J33: =I33 -> -995290.17 | K33: =I33-J33 -> 0 | L33: =I33-J33-K33 -> 0
A34: Liabilities | B34: 11000005 | C34: 19 | D34: Other Current Liabilities | E34: Statutory liabilities | F34: TDS_Rent_194I | G34: 0 | H34: -21113 | I34: =G34+H34 -> -21113 | J34: =I34 -> -21113 | K34: =I34-J34 -> 0 | L34: =I34-J34-K34 -> 0
A35: Liabilities | B35: 11000006 | C35: 19 | D35: Other Current Liabilities | E35: Statutory liabilities | F35: TDS_Purchase on Goods_194Q | G35: 0 | H35: -64627 | I35: =G35+H35 -> -64627 | J35: =I35 -> -64627 | K35: =I35-J35 -> 0 | L35: =I35-J35-K35 -> 0
A36: Liabilities | B36: 11000007 | C36: 19 | D36: Other Current Liabilities | E36: Statutory liabilities | F36: TDS_Salary_192 | G36: 0 | H36: -627704 | I36: =G36+H36 -> -627704 | J36: =I36 -> -627704 | K36: =I36-J36 -> 0 | L36: =I36-J36-K36 -> 0
A37: Liabilities | B37: 11000011 | C37: 19 | D37: Other Current Liabilities | E37: Statutory liabilities | F37: PF Employee Contribution | G37: 0 | H37: -288873 | I37: =G37+H37 -> -288873 | J37: =I37 -> -288873 | K37: =I37-J37 -> 0 | L37: =I37-J37-K37 -> 0
A38: Liabilities | B38: 11000012 | C38: 19 | D38: Other Current Liabilities | E38: Statutory liabilities | F38: Professional Tax | G38: 0 | H38: -31400 | I38: =G38+H38 -> -31400 | J38: =I38 -> -31400 | K38: =I38-J38 -> 0 | L38: =I38-J38-K38 -> 0
A39: Liabilities | B39: 11100002 | C39: 18 | D39: Other financial liabilities | E39: Payable for capital goods (including retention amount) | F39: Retention Money | G39: 0 | H39: -1.0417368e+08 | I39: =G39+H39 -> -1.0417368e+08 | J39: =I39 -> -1.0417368e+08 | K39: =I39-J39 -> 0 | L39: =I39-J39-K39 -> 0
A40: Liabilities | B40: 21000008 | C40: 19 | D40: Other Current Liabilities | E40: Statutory liabilities | F40: CGST Payable | G40: 0 | H40: -16738.64 | I40: =G40+H40 -> -16738.64 | J40: =I40 -> -16738.64 | K40: =I40-J40 -> 0 | L40: =I40-J40-K40 -> 0
...

Sheet TB BVS 31.03.26
G1: BS | H1: CFS | I1: =I4/100000 -> -23491.916 | J1: =+('TB BVS 31.03.26'!I17+'TB BVS 31.03.26'!I76)/1000 -> -142.60621
G2: 106141.52 | H2: #REF! | I2: =I3+I4 -> -1.3965967e+09
A3: =Input!B1 -> BVC Specialities Private Limited | I3: 952594932 | J3: -19095.661
A4: Trial Balance as on 31st March 2026 | I4: =SUBTOTAL(9,I7:I971) -> -2.3491916e+09 | J4: =SUBTOTAL(9,J7:J971) -> 0 | K4: =SUBTOTAL(9,K7:K971) -> 0 | L4: =SUBTOTAL(9,L7:L971) -> 0 | O4: =O5/1000000 -> 0 | P4: =P5/1000000 -> 0 | AC4: =I4/1000000 -> -2349.1916 | AD4: 3151
C5: Ind AS | D5: Ind AS | E5: Ind AS | O5: =SUBTOTAL(9,O130:O217) -> 0 | P5: =SUBTOTAL(9,P130:P217) -> 0
A6: Type | B6: Code No. | C6: Note | D6: Ind AS Head | E6: Ind AS Sub Head | F6: Particulars | G6: Debit | H6: Credit | I6: Total | J6: Current | K6: Non-Current | L6: Check | O6: Nov | P6: July
A7: Equity | B7: 10000000 | C7: 12 | D7: Equity share capital | E7: 315,940 (previous year: 315,940) equity shares of Rs 10 each fully paid up | F7: Equity Share Capital | G7: =IFERROR(VLOOKUP(B7,[5]Sheet1!$C:$M,8,0),0) -> 0 | H7: =IFERROR(VLOOKUP(B7,[5]Sheet1!$C:$M,9,0),0) -> -1597890 | I7: =G7+H7 -> -1597890 | J7: 0 | K7: 0 | M7: =VLOOKUP(B7,[6]Sheet1!$D:$M,10,0) -> -1365970 | N7: =I7-M7 -> -231920 | T7: =VLOOKUP(B7,[7]!Table1[GLAccountNo],1,0) -> #REF!
A8: Equity | B8: 10000004 | C8: 12 | D8: Other equity | E8: Pref Shar CCPS-BVCPL | F8: 0.01% Non-Cumulative CCPS | G8: =IFERROR(VLOOKUP(B8,[5]Sheet1!$C:$M,8,0),0) -> 0 | H8: =IFERROR(VLOOKUP(B8,[5]Sheet1!$C:$M,9,0),0) -> -1999973649 | I8: =G8+H8 -> -1999973649 | J8: 0 | K8: 0 | M8: =VLOOKUP(B8,[6]Sheet1!$D:$M,10,0) -> -868680 | N8: =I8-M8 -> -1999104969
A9: Equity | B9: 10100000 | C9: 13 | D9: Other equity | E9: Closing balance - Securities Premium | F9: Security Premium Account | G9: =IFERROR(VLOOKUP(B9,[5]Sheet1!$C:$M,8,0),0) -> 0 | H9: =IFERROR(VLOOKUP(B9,[5]Sheet1!$C:$M,9,0),0) -> -1.5602377e+09 | I9: =G9+H9 -> -1.5602377e+09 | J9: 0 | K9: 0 | M9: =VLOOKUP(B9,[6]Sheet1!$D:$M,10,0) -> -2.8885604e+09 | N9: =I9-M9 -> 1328322752 | P9: Opening | Q9: CY | R9: Closing
A10: Equity | B10: 10100001 | C10: 13 | D10: Other equity | E10: Closing balance - Retained Earnings | F10: Retained earnings | G10: =IFERROR(VLOOKUP(B10,[5]Sheet1!$C:$M,8,0),0) -> 2.0525541e+08 | H10: =IFERROR(VLOOKUP(B10,[5]Sheet1!$C:$M,9,0),0) -> 0 | I10: =G10+H10 -> 2.0525541e+08 | J10: 0 | K10: 0 | M10: =VLOOKUP(B10,[6]Sheet1!$D:$M,10,0) -> 2.0525541e+08 | N10: =I10-M10 -> 0 | P10: =-'BS Notes 3-18'!H243*1000 -> 2029035.2 | Q10: 386615.03 | R10: =SUBTOTAL(9,P10:Q10) -> 0
A11: Equity | B11: 10100002 | C11: 13 | D11: Other equity | E11: Closing balance - Retained Earnings | F11: Profit & Loss Account | G11: =IFERROR(VLOOKUP(B11,[5]Sheet1!$C:$M,8,0),0) -> 7941080.5 | H11: =IFERROR(VLOOKUP(B11,[5]Sheet1!$C:$M,9,0),0) -> 0 | I11: =G11+H11 -> 7941080.5 | J11: 0 | K11: 0 | M11: =VLOOKUP(B11,[6]Sheet1!$D:$M,10,0) -> 7941080.5 | N11: =I11-M11 -> 0 | P11: =I11 -> 7941080.5 | R11: =SUBTOTAL(9,P11:Q11) -> 0
A12: Equity | B12: 10100009 | C12: 13 | D12: Other equity | E12: Closing balance - Retained Earnings | F12: IND AS - Opening Balance - Retained Earnings | G12: =IFERROR(VLOOKUP(B12,[5]Sheet1!$C:$M,8,0),0) -> 0 | H12: =IFERROR(VLOOKUP(B12,[5]Sheet1!$C:$M,9,0),0) -> -38668.9 | I12: =G12+H12 -> -38668.9 | J12: 0 | K12: 0 | M12: =VLOOKUP(B12,[6]Sheet1!$D:$M,10,0) -> -38668.9 | N12: =I12-M12 -> 0 | P12: =I12 -> -38668.9 | R12: =SUBTOTAL(9,P12:Q12) -> 0
A13: Liabilities | B13: 10200015 | C13: 14 | D13: Borrowings | E13: Term Loan from Bank* | F13: IND AS - Transaction Cost Impact on TL | G13: =IFERROR(VLOOKUP(B13,[5]Sheet1!$C:$M,8,0),0) -> 2147916.4 | H13: =IFERROR(VLOOKUP(B13,[5]Sheet1!$C:$M,9,0),0) -> 0 | I13: =G13+H13 -> 2147916.4 | J13: 0 | K13: =I13-J13 -> 2147916.4 | L13: =I13-J13-K13 -> 0 | M13: =VLOOKUP(B13,[6]Sheet1!$D:$M,10,0) -> 1223808.4 | N13: =I13-M13 -> 924108
A14: Liabilities | B14: 10200016 | C14: 14 | D14: Borrowings | E14: Term Loan from Bank* | F14: TL_AXIS_ 923060053143888 | G14: =IFERROR(VLOOKUP(B14,[5]Sheet1!$C:$M,8,0),0) -> 0 | H14: =IFERROR(VLOOKUP(B14,[5]Sheet1!$C:$M,9,0),0) -> -1.7669e+09 | I14: =G14+H14 -> -1.7669e+09 | J14: -399600000 | K14: =I14-J14 -> -1.3673e+09 | L14: =I14-J14-K14 -> 0 | M14: =VLOOKUP(B14,[6]Sheet1!$D:$M,10,0) -> -2000000000 | N14: =I14-M14 -> 2.331e+08
A15: Liabilities | B15: 10200018 | C15: 14 | D15: Borrowings | E15: Term Loan from Bank* | F15: TL_AXIS_924060051723539 | G15: =IFERROR(VLOOKUP(B15,[5]Sheet1!$C:$M,8,0),0) -> 0 | H15: =IFERROR(VLOOKUP(B15,[5]Sheet1!$C:$M,9,0),0) -> -362015481 | I15: =G15+H15 -> -362015481 | J15: -80400000 | K15: =I15-J15 -> -281615481 | L15: =I15-J15-K15 -> 0 | M15: =VLOOKUP(B15,[6]Sheet1!$D:$M,10,0) -> -400000000 | N15: =I15-M15 -> 37984519
A16: Liabilities | B16: 10300002 | C16: 14 | D16: Borrowings | E16: Term Loan from Bank* | F16: TL_HDFC_02400930000746 | G16: =IFERROR(VLOOKUP(B16,[5]Sheet1!$C:$M,8,0),0) -> 0 | H16: =IFERROR(VLOOKUP(B16,[5]Sheet1!$C:$M,9,0),0) -> -3.4999916e+08 | I16: =G16+H16 -> -3.4999916e+08 | J16: -99999761 | K16: =I16-J16 -> -2.499994e+08 | L16: =I16-J16-K16 -> 0 | M16: =VLOOKUP(B16,[6]Sheet1!$D:$M,10,0) -> -3.9999904e+08 | N16: =I16-M16 -> 49999880
A17: Liabilities | B17: 10400001 | C17: 16 | D17: Deferred Tax Liabilities (Net) | E17: Deferred Tax | F17: IND AS - Deferred Tax Liability | G17: 0 | H17: -238523.49 | I17: =G17+H17 -> -238523.49 | K17: =I17-J17 -> -238523.49 | L17: =I17-J17-K17 -> 0 | M17: =VLOOKUP(B17,[6]Sheet1!$D:$M,10,0) -> -238523.49 | N17: =I17-M17 -> 0
A18: Liabilities | B18: 10500000 | C18: 15 | D18: Provisions | E18: Provision for employee benefits - Gratuity | F18: Provision for Gratuity | G18: =IFERROR(VLOOKUP(B18,[5]Sheet1!$C:$M,8,0),0) -> 0 | H18: =IFERROR(VLOOKUP(B18,[5]Sheet1!$C:$M,9,0),0) -> -4499741 | I18: =G18+H18 -> -4499741 | J18: -443965 | K18: =I18-J18 -> -4055776 | L18: =I18-J18-K18 -> 0 | M18: =VLOOKUP(B18,[6]Sheet1!$D:$M,10,0) -> -2120219 | N18: =I18-M18 -> -2379522
A19: Liabilities | B19: 10500001 | C19: 15 | D19: Provisions | E19: Provision for compensated absences | F19: Provision for Leave Salary | G19: =IFERROR(VLOOKUP(B19,[5]Sheet1!$C:$M,8,0),0) -> 0 | H19: =IFERROR(VLOOKUP(B19,[5]Sheet1!$C:$M,9,0),0) -> -4772879 | I19: =G19+H19 -> -4772879 | J19: -824137 | K19: =I19-J19 -> -3948742 | L19: =I19-J19-K19 -> 0 | M19: =VLOOKUP(B19,[6]Sheet1!$D:$M,10,0) -> -2607951 | N19: =I19-M19 -> -2164928
A20: Liabilities | B20: 10600010 | C20: 14 | D20: Borrowings | E20: Unsecured loan from related parties | F20: Best Value Chem Pvt Ltd. | G20: =IFERROR(VLOOKUP(B20,[5]Sheet1!$C:$M,8,0),0) -> 0 | H20: =IFERROR(VLOOKUP(B20,[5]Sheet1!$C:$M,9,0),0) -> -0.41 | I20: =G20+H20 -> -0.41 | J20: 0 | K20: 0 | M20: =VLOOKUP(B20,[6]Sheet1!$D:$M,10,0) -> -2.6596834e+08 | N20: =I20-M20 -> 265968343
A21: Liabilities | B21: 10800000 | C21: 17 | D21: Trade payables | E21: Total outstanding dues of creditors other than micro enterprises and small enterprises | F21: Payable - Raw Material Import | G21: =IFERROR(VLOOKUP(B21,[5]Sheet1!$C:$M,8,0),0) -> 0 | H21: =IFERROR(VLOOKUP(B21,[5]Sheet1!$C:$M,9,0),0) -> -1.263965e+08 | I21: =G21+H21 -> -1.263965e+08 | J21: 0 | K21: 0 | M21: =VLOOKUP(B21,[6]Sheet1!$D:$M,10,0) -> -84434755 | N21: =I21-M21 -> -41961748
A22: Liabilities | B22: 10800001 | C22: 17 | D22: Trade payables | E22: Total outstanding dues of creditors other than micro enterprises and small enterprises | F22: Payable - Raw Material Domestic | G22: =IFERROR(VLOOKUP(B22,[5]Sheet1!$C:$M,8,0),0) -> 0 | H22: =IFERROR(VLOOKUP(B22,[5]Sheet1!$C:$M,9,0),0) -> -1.5433134e+08 | I22: =G22+H22 -> -1.5433134e+08 | J22: 0 | K22: 0 | M22: =VLOOKUP(B22,[6]Sheet1!$D:$M,10,0) -> -99935999 | N22: =I22-M22 -> -54395339 | Q22: ='[8]BVC Sale'!$D$272*0 -> 0
A23: Liabilities | B23: 10800002 | C23: 17 | D23: Trade payables | E23: Total outstanding dues of creditors other than micro enterprises and small enterprises | F23: Payable - Packing Material | G23: =IFERROR(VLOOKUP(B23,[5]Sheet1!$C:$M,8,0),0) -> 0 | H23: =IFERROR(VLOOKUP(B23,[5]Sheet1!$C:$M,9,0),0) -> -14985765 | I23: =G23+H23 -> -14985765 | J23: 0 | K23: 0 | M23: =VLOOKUP(B23,[6]Sheet1!$D:$M,10,0) -> -7862613.2 | N23: =I23-M23 -> -7123152.1 | AD23: 6106184 | AE23: Packing Material Adj - Out of books
A24: Liabilities | B24: 10800003 | C24: 17 | D24: Trade payables | E24: Total outstanding dues of creditors other than micro enterprises and small enterprises | F24: Payable - Fuel | G24: =IFERROR(VLOOKUP(B24,[5]Sheet1!$C:$M,8,0),0) -> 0 | H24: =IFERROR(VLOOKUP(B24,[5]Sheet1!$C:$M,9,0),0) -> -18468224 | I24: =G24+H24 -> -18468224 | J24: 0 | K24: 0 | M24: =VLOOKUP(B24,[6]Sheet1!$D:$M,10,0) -> -7541013.5 | N24: =I24-M24 -> -10927211
A25: Liabilities | B25: 10800004 | C25: 17 | D25: Trade payables | E25: Total outstanding dues of creditors other than micro enterprises and small enterprises | F25: Payable - Others | G25: =IFERROR(VLOOKUP(B25,[5]Sheet1!$C:$M,8,0),0) -> 0 | H25: =IFERROR(VLOOKUP(B25,[5]Sheet1!$C:$M,9,0),0) -> -6.7466306e+08 | I25: =G25+H25 -> -6.7466306e+08 | J25: 0 | K25: 0 | M25: =VLOOKUP(B25,[6]Sheet1!$D:$M,10,0) -> -3.1699296e+08 | N25: =I25-M25 -> -3.5767009e+08
A26: Liabilities | B26: 10800005 | C26: 18 | D26: Other financial liabilities | E26: Employee benefits payable | F26: Payables - Employees | G26: =IFERROR(VLOOKUP(B26,[5]Sheet1!$C:$M,8,0),0) -> 42051.22 | H26: =IFERROR(VLOOKUP(B26,[5]Sheet1!$C:$M,9,0),0) -> 0 | I26: =G26+H26 -> 42051.22 | J26: 0 | K26: 0 | M26: =VLOOKUP(B26,[6]Sheet1!$D:$M,10,0) -> 35924.22 | N26: =I26-M26 -> 6127
A27: Liabilities | B27: 10900000 | C27: 17 | D27: Trade payables | E27: Total outstanding dues of creditors other than micro enterprises and small enterprises | F27: Provision_Other Expenses | G27: =IFERROR(VLOOKUP(B27,[5]Sheet1!$C:$M,8,0),0) -> 0 | H27: =IFERROR(VLOOKUP(B27,[5]Sheet1!$C:$M,9,0),0) -> -6785728.3 | I27: =G27+H27 -> -6785728.3 | J27: 0 | K27: 0 | M27: =VLOOKUP(B27,[6]Sheet1!$D:$M,10,0) -> -8925974 | N27: =I27-M27 -> 2140245.7
A28: Liabilities | B28: 20100001 | C28: 17 | D28: Trade payables | E28: Total outstanding dues of creditors other than micro enterprises and small enterprises | F28: Capital Advances | G28: =IFERROR(VLOOKUP(B28,[5]Sheet1!$C:$M,8,0),0) -> 1224019.4 | H28: =IFERROR(VLOOKUP(B28,[5]Sheet1!$C:$M,9,0),0) -> 0 | I28: =G28+H28 -> 1224019.4 | J28: 0 | K28: 0 | M28: =VLOOKUP(B28,[6]Sheet1!$D:$M,10,0) -> 8778690 | N28: =I28-M28 -> -7554670.6
A29: Liabilities | B29: 10900003 | C29: 19 | D29: Other Current Liabilities | E29: Statutory liabilities | F29: Provision_PF and ESIC Contribution by Company | G29: =IFERROR(VLOOKUP(B29,[5]Sheet1!$C:$M,8,0),0) -> 0 | H29: =IFERROR(VLOOKUP(B29,[5]Sheet1!$C:$M,9,0),0) -> -461147 | I29: =G29+H29 -> -461147 | J29: 0 | K29: 0 | M29: =VLOOKUP(B29,[6]Sheet1!$D:$M,10,0) -> -311807 | N29: =I29-M29 -> -149340
A30: Liabilities | B30: 10900018 | C30: 18 | D30: Other financial liabilities | E30: Employee benefits payable | F30: Salary Payable | G30: =IFERROR(VLOOKUP(B30,[5]Sheet1!$C:$M,8,0),0) -> 0 | H30: =IFERROR(VLOOKUP(B30,[5]Sheet1!$C:$M,9,0),0) -> -119680.01 | I30: =G30+H30 -> -119680.01 | J30: 0 | K30: 0 | M30: =VLOOKUP(B30,[6]Sheet1!$D:$M,10,0) -> -9835879.2 | N30: =I30-M30 -> 9716199.2
A31: Liabilities | B31: 11000001 | C31: 19 | D31: Other Current Liabilities | E31: Statutory liabilities | F31: TDS_Professional and Consulting_194J | G31: =IFERROR(VLOOKUP(B31,[5]Sheet1!$C:$M,8,0),0) -> 0 | H31: =IFERROR(VLOOKUP(B31,[5]Sheet1!$C:$M,9,0),0) -> -382362.06 | I31: =G31+H31 -> -382362.06 | J31: 0 | K31: 0 | M31: =VLOOKUP(B31,[6]Sheet1!$D:$M,10,0) -> 53941.44 | N31: =I31-M31 -> -436303.5
A32: Liabilities | B32: 11000002 | C32: 19 | D32: Other Current Liabilities | E32: Statutory liabilities | F32: TDS_Contractors_194C | G32: =IFERROR(VLOOKUP(B32,[5]Sheet1!$C:$M,8,0),0) -> 0 | H32: =IFERROR(VLOOKUP(B32,[5]Sheet1!$C:$M,9,0),0) -> -3257917.5 | I32: =G32+H32 -> -3257917.5 | J32: 0 | K32: 0 | M32: =VLOOKUP(B32,[6]Sheet1!$D:$M,10,0) -> -336176.31 | N32: =I32-M32 -> -2921741.2
A33: Liabilities | B33: 11000003 | C33: 19 | D33: Other Current Liabilities | E33: Statutory liabilities | F33: TDS_Interest on borrowing_194A | G33: =IFERROR(VLOOKUP(B33,[5]Sheet1!$C:$M,8,0),0) -> 0 | H33: =IFERROR(VLOOKUP(B33,[5]Sheet1!$C:$M,9,0),0) -> -0.17 | I33: =G33+H33 -> -0.17 | J33: 0 | K33: 0 | M33: =VLOOKUP(B33,[6]Sheet1!$D:$M,10,0) -> 501331.83 | N33: =I33-M33 -> -501332
A34: Liabilities | B34: 11000005 | C34: 19 | D34: Other Current Liabilities | E34: Statutory liabilities | F34: TDS_Rent_194I | G34: =IFERROR(VLOOKUP(B34,[5]Sheet1!$C:$M,8,0),0) -> 0 | H34: =IFERROR(VLOOKUP(B34,[5]Sheet1!$C:$M,9,0),0) -> -75369 | I34: =G34+H34 -> -75369 | J34: 0 | K34: 0 | M34: =VLOOKUP(B34,[6]Sheet1!$D:$M,10,0) -> 9503 | N34: =I34-M34 -> -84872
A35: Liabilities | B35: 11000006 | C35: 19 | D35: Other Current Liabilities | E35: Statutory liabilities | F35: TDS_Purchase on Goods_194Q | G35: =IFERROR(VLOOKUP(B35,[5]Sheet1!$C:$M,8,0),0) -> 0 | H35: =IFERROR(VLOOKUP(B35,[5]Sheet1!$C:$M,9,0),0) -> -224723.73 | I35: =G35+H35 -> -224723.73 | J35: 0 | K35: 0 | M35: =VLOOKUP(B35,[6]Sheet1!$D:$M,10,0) -> -63397.5 | N35: =I35-M35 -> -161326.23
... A67: Asset | B67: 20100004 | C67: 3 | D67: Property, Plant and Equipment | E67: Capital work-in-progress | F67: AUC Cost | G67: =IFERROR(VLOOKUP(B67,[5]Sheet1!$C:$M,8,0),0) -> 41000 | H67: =IFERROR(VLOOKUP(B67,[5]Sheet1!$C:$M,9,0),0) -> 0 | I67: =G67+H67 -> 41000 | J67: 0 | K67: 0 | M67: =VLOOKUP(B67,[6]Sheet1!$D:$M,10,0) -> 41000 | N67: =I67-M67 -> 0
A68: Asset | B68: 40700034 | C68: 3 | D68: Property, Plant and Equipment | E68: Capital work-in-progress | F68: Project Expenses | G68: =IFERROR(VLOOKUP(B68,[5]Sheet1!$C:$M,8,0),0) -> 0 | H68: =IFERROR(VLOOKUP(B68,[5]Sheet1!$C:$M,9,0),0) -> 0 | I68: =G68+H68 -> 0 | J68: 0 | K68: 0 | M68: =VLOOKUP(B68,[6]Sheet1!$D:$M,10,0) -> -32419216 | N68: =I68-M68 -> 32419216 | Q68: =VLOOKUP(B68,[7]!Table1[GLAccountNo],1,0) -> #REF!
A69: Asset | B69: 20000005 | C69: 3 | D69: Property, Plant and Equipment | E69: Office Equipment | F69: Office Equipment | G69: =IFERROR(VLOOKUP(B69,[5]Sheet1!$C:$M,8,0),0) -> 19595727 | H69: =IFERROR(VLOOKUP(B69,[5]Sheet1!$C:$M,9,0),0) -> 0 | I69: =G69+H69 -> 19595727 | J69: 0 | K69: 0 | M69: =VLOOKUP(B69,[6]Sheet1!$D:$M,10,0) -> 19595727 | N69: =I69-M69 -> 0
A70: Asset | B70: 20000009 | C70: 3 | D70: Property, Plant and Equipment | E70: Furniture & Fixture | F70: Furniture & Fixture | G70: =IFERROR(VLOOKUP(B70,[5]Sheet1!$C:$M,8,0),0) -> 20587570 | H70: =IFERROR(VLOOKUP(B70,[5]Sheet1!$C:$M,9,0),0) -> 0 | I70: =G70+H70 -> 20587570 | J70: 0 | K70: 0 | M70: =VLOOKUP(B70,[6]Sheet1!$D:$M,10,0) -> 20587570 | N70: =I70-M70 -> 0
A71: Asset | B71: 20000011 | C71: 3 | D71: Property, Plant and Equipment | E71: Electrical Fittings | F71: Electrical Fittings | G71: =IFERROR(VLOOKUP(B71,[5]Sheet1!$C:$M,8,0),0) -> 1.3395587e+08 | H71: =IFERROR(VLOOKUP(B71,[5]Sheet1!$C:$M,9,0),0) -> 0 | I71: =G71+H71 -> 1.3395587e+08 | J71: 0 | K71: 0 | M71: =VLOOKUP(B71,[6]Sheet1!$D:$M,10,0) -> 1.3349476e+08 | N71: =I71-M71 -> 461110.11
...

Sheet BS
A1: =Input!$B$1 -> BVC Specialities Private Limited
A2: Balance Sheet as at 31 March 2026
E3: =Input!$D$2 -> (₹ in Lakh) | F3: =Input!$D$2 -> (₹ in Lakh)
A4: Particulars | C4: Note | D4: As at | E4: As at | F4: As at | I4: As at
D5: 31 March 2026 | E5: 31 March 2025 | F5: =Input!C6 -> 31 March 2022 | H5: =D8*1000 -> 47317815 | I5: 31 March 2026 | R5: =H5/100000 -> 473.17815
B6: ASSETS | H6: =5344-5331 -> 13
B7: Non Current Assets
A8: (a) | B8: Property, Plant & Equipment | C8: =Input!$D$13 -> 3 | D8: ='PPE- note 3'!J17 -> 47317.815 | E8: =5019438.923/100 -> 50194.389 | F8: 0 | H8: =E8-D8 -> 2876.5741 | I8: 47317.315 | J8: =D8-I8 -> 0.5 | K8: =D8-I8 -> 0.5 | N8: =ROUND(SUMIF('TB BVS 31.3.22'!E:E,BS!B8,'TB BVS 31.3.22'!N:N)/Input!$C$2,Input!$E$2)-F8 -> 0 | O8: Check | R8: Sampling done we have not received samples yet
A9: (b) | B9: Right of Use Assets | C9: =Input!$D$13 -> 3 | D9: ='PPE- note 3'!J23 -> 3116.3267 | E9: =315093/100 -> 3150.93 | F9: ='PPE- note 3'!K127 -> 1646 | H9: =E9-D9 -> 34.603343 | I9: 3116.3267 | J9: =D9-I9 -> 0
A10: (c) | B10: Capital work-in-progress | C10: =Input!$D$13 -> 3 | D10: ='PPE- note 3'!J18 -> 1149.427 | E10: 0 | F10: ='PPE- note 3'!K123 -> 0 | G10: =D10-[4]BS!$D$10 -> -3160244.4 | H10: =E10-D10 -> -1149.427 | I10: 1149.427 | J10: =D10-I10 -> 0 | R10: =D10/1000 -> 1.149427
A11: (d) | B11: Intangible assets | C11: =Input!$D$13 -> 3 | D11: ='PPE- note 3'!J27 -> 29.181997 | E11: =4365/100 -> 43.65 | F11: 0 | H11: =E11-D11 -> 14.468003 | I11: 29.181997 | J11: =D11-I11 -> 0
A12: (e) | B12: Financial Assets | H12: =E12-D12 -> 0 | J12: =D12-I12 -> 0
B13: (i) Investments | C13: 4 | D13: ='BS Notes 3-18'!G11 -> 17 | E13: 0 | H13: =E13-D13 -> -17 | I13: 17 | J13: =D13-I13 -> 0
B14: (ii) Loans | C14: 5 | D14: ='BS Notes 3-18'!G21 -> 0 | E14: ='BS Notes 3-18'!H21 -> 0 | H14: =E14-D14 -> 0 | I14: 0 | J14: =D14-I14 -> 0
B15: (ii) Other Financial Assets | C15: 5 | D15: ='BS Notes 3-18'!G33 -> 307 | E15: ='BS Notes 3-18'!H33 -> 352 | H15: =E15-D15 -> 45 | I15: 307 | J15: =D15-I15 -> 0 | R15: Done
A16: (f) | B16: Deferred Tax Assets (Net) | C16: 16 | D16: ='BS Notes 3-18'!G328 -> 1586.3847 | E16: ='BS Notes 3-18'!H329 -> 0 | F16: =-'BS Notes 3-18'!I328 -> 0 | H16: =E16-D16 -> -1586.3847 | I16: 0 | J16: =D16-I16 -> 1586.3847
A17: (g) | B17: Other Tax Assets (Net) | C17: 6 | D17: ='BS Notes 3-18'!G44 -> 5.5 | E17: ='BS Notes 3-18'!H44 -> 13 | H17: =E17-D17 -> 7.5 | I17: 5.5 | J17: =D17-I17 -> 0 | R17: Rahul
A18: (h) | B18: Other Non Current Assets | C18: 7 | D18: ='BS Notes 3-18'!G54 -> 75.5 | E18: ='BS Notes 3-18'!H54 -> 84 | H18: =E18-D18 -> 8.5 | I18: 76.5 | J18: =D18-I18 -> -1
B19: Total Non Current Assets | D19: =SUM(D8:D18) -> 53604.135 | E19: =SUM(E8:E18) -> 53837.969 | F19: =SUM(F8:F11) -> 1646 | I19: 52018.251 | J19: =D19-I19 -> 1585.8847
J20: =D20-I20 -> 0
B21: Current Assets | J21: =D21-I21 -> 0
A22: (a) | B22: Inventories | C22: 8 | D22: ='BS Notes 3-18'!G76 -> 6638 | E22: ='BS Notes 3-18'!H76 -> 811 | H22: =E22-D22 -> -5827 | I22: 6638 | J22: =D22-I22 -> 0 | R22: Pending
A23: (b) | B23: Financial Assets | H23: =E23-D23 -> 0 | J23: =D23-I23 -> 0
B24: (i) Trade Receivables | C24: 9 | D24: ='BS Notes 3-18'!G90 -> 3026 | E24: ='BS Notes 3-18'!H90 -> 454 | H24: =E24-D24 -> -2572 | I24: 3026 | J24: =D24-I24 -> 0 | R24: done
B25: (ii) Cash and Cash Equivalents | C25: 10 | D25: ='BS Notes 3-18'!G118 -> 31 | E25: ='BS Notes 3-18'!H118 -> 22 | F25: ='BS Notes 3-18'!I118 -> 24 | H25: =E25-D25 -> -9 | I25: 31 | J25: =D25-I25 -> 0 | R25: done | S25: reclass pending
A26: (c) | B26: Current Tax Assets (net) | C26: 7 | D26: ='BS Notes 3-18'!G48 -> 0 | E26: 0 | H26: =E26-D26 -> 0 | I26: 0 | J26: =D26-I26 -> 0
B27: (iii) Other Financial Assets | D27: ='BS Notes 3-18'!G36 -> 0 | I27: 0 | J27: =D27-I27 -> 0 | R27: pending
B28: (iii) Bank balances other than (ii) above | C28: 10 | D28: ='BS Notes 3-18'!G122 -> 54 | E28: 0 | H28: =E28-D28 -> -54 | I28: 54 | J28: =D28-I28 -> 0
A29: (c) | B29: Other Current Assets | C29: 11 | D29: ='BS Notes 3-18'!G131 -> 6155.5 | E29: ='BS Notes 3-18'!H131 -> 5212 | F29: ='BS Notes 3-18'!I131 -> 296 | G29: navaz | H29: =E29-D29 -> -943.5 | I29: 6155 | J29: =D29-I29 -> 0.5 | R29: Done
B30: Total Current Assets | D30: =SUM(D22:D29) -> 15904.5 | E30: =SUM(E22:E29) -> 6499 | F30: =SUM(F23:F29) -> 320 | G30: =D30/10000 -> 1.59045 | I30: 15904 | J30: =D30-I30 -> 0.5
B31: Total Assets | D31: =D19+D30 -> 69508.635 | E31: =E19+E30 -> 60336.969 | F31: =F19+F30 -> 1966 | H31: 6.424212e+09 | I31: 67922.251 | J31: =D31-I31 -> 1586.3847 | R31: =D31*1000 -> 69508635 | S31: =R31-H31 -> -6.3547033e+09 | T31: =S31/1000 -> -6354703.3
J32: =D32-I32 -> 0
B33: EQUITY AND LIABILITIES | J33: =D33-I33 -> 0
B34: Equity | J34: =D34-I34 -> 0
A35: (a) | B35: Equity Share Capital | C35: 12 | D35: ='BS Notes 3-18'!G146 -> 15.9789 | E35: ='BS Notes 3-18'!H146 -> 13.6597 | F35: ='BS Notes 3-18'!I146 -> 100 | H35: =D35-E35 -> 2.3192 | I35: 15.9789 | J35: =D35-I35 -> 0
A36: (b) | B36: Instrument entirely equity in nature | C36: 12 | D36: ='BS Notes 3-18'!G197 -> 9.1868 | E36: ='BS Notes 3-18'!H181+'BS Notes 3-18'!H188 -> 9.1868 | H36: =D36-E36 -> 0 | I36: 8.6868 | J36: =D36-I36 -> 0.5
A37: (c) | B37: Other Equity | C37: 13 | D37: ='BS Notes 3-18'!G227 -> 27519.019 | E37: ='BS Notes 3-18'!H227 -> 26755.436 | F37: ='BS Notes 3-18'!I227 -> #REF! | H37: =D37-E37 -> 763.58221 | I37: 25906.759 | J37: =D37-I37 -> 1612.26 | L37: ='BS Notes 3-18'!L224 -> 0 | N37: =H35 -> 2.3192 | O37: Equity component of Compound Financial Instruments | R37: =E37-D37 -> -763.58221
B38: Total Equity | D38: =SUM(D35:D37) -> 27544.184 | E38: =SUM(E35:E37) -> 26778.283 | F38: =SUM(F35:F37) -> #REF! | G38: =D38-E38 -> 765.90141 | H38: =D38-E38 -> 765.90141 | I38: 25931.424 | J38: =D38-I38 -> 1612.76 | L38: ='BS Notes 3-18'!L225 -> 6708.8222 | N38: ='BS Notes 3-18'!O225 -> 6708.8222 | O38: Securities premium
J39: =D39-I39 -> 0 | L39: ='BS Notes 3-18'!L226 -> -5945.24 | N39: ='BS Notes 3-18'!O226 -> -5945.24 | O39: Retained earnings
B40: Liabilities | J40: =D40-I40 -> 0 | L40: =SUM(L37:L39) -> 763.58221
...

Sheet PL
A1: =Input!$B$1 -> BVC Specialities Private Limited
A2: Statement of Profit and Loss for the Year Ended 31 March 2026
E3: =Input!$D$2 -> (₹ in Lakh) | F3: =Input!$D$2 -> (₹ in Lakh)
A4: Particulars | C4: Note | D4: Year Ended | E4: Year Ended | F4: Year Ended
D5: =BS!D5 -> 31 March 2026 | E5: =BS!E5 -> 31 March 2025 | F5: March 31,2022
B7: Income
A8: I | B8: Revenue from Operations | C8: 20 | D8: ='PL Notes 19-27'!C17 -> 23491 | E8: ='PL Notes 19-27'!D17 -> 1094 | F8: ='[2]PL Notes 19-26'!E17 -> 0 | G8: 70109.418 | H8: =E8-G8 -> -69015.418 | I8: Ok | Q8: Tomorrow | R8: 40277
A9: II | B9: Other Income | C9: 21 | D9: ='PL Notes 19-27'!C36 -> 238 | E9: ='PL Notes 19-27'!D36 -> 73 | F9: ='[2]PL Notes 19-26'!E34 -> 0 | G9: 682.34518 | H9: =E9-G9 -> -609.34518 | I9: Refer Note | Q9: Tomorrow | R9: =R11/R8 -> 0.38246817 | S9: =S11/E8 -> 0.37463633
A10: III | B10: Total Income (I+II) | D10: =SUM(D8:D9) -> 23729 | E10: =SUM(E8:E9) -> 1167 | F10: =SUM(F8:F9) -> 0 | G10: =SUM(G8:G9) -> 70791.763 | H10: =SUM(H8:H9) -> -69624.763
R11: =D13+D15 -> 15404.67 | S11: =E13+E15 -> 409.85214
A12: II | B12: Expenses | G12: =D10*1000 -> 23729000
B13: Cost of materials consumed | C13: =C9+1 -> 22 | D13: ='PL Notes 19-27'!C51 -> 19619.67 | E13: ='PL Notes 19-27'!D51-E14 -> 796.74214 | F13: ='[2]PL Notes 19-26'!E42+'[2]PL Notes 19-26'!E47 -> 0 | G13: 44527.472 | H13: =E13-G13 -> -43730.73 | I13: Due to Impact of Change in Inv method | Q13: Tomorrow | T13: =(D13+D15)/$D$10 -> 0.64919172 | U13: =(E13+E15)/$E$10 -> 0.35120149
B14: Purchase of stock-in-trade (traded goods) | C14: - | D14: 2112.3297 | E14: =115.837859278726 -> 115.83786 | R14: =D14*100000 -> 2.1123297e+08
B15: Changes in inventories of finished goods and work-in-progress | C15: =C13+1 -> 23 | D15: ='PL Notes 19-27'!C64 -> -4215 | E15: ='PL Notes 19-27'!D64 -> -386.89 | F15: ='[2]PL Notes 19-26'!E62 -> 0 | G15: -1566.3014 | H15: =E15-G15 -> 1179.4114 | I15: Due to Impact of Change in Inv method | Q15: Tomorrow
B16: Employee Benefits Expense | C16: =C15+1 -> 24 | D16: ='PL Notes 19-27'!C74 -> 1989.5569 | E16: ='PL Notes 19-27'!D74 -> 147.7747 | Q16: Navaz | R16: =D19/10 -> 588.3 | T16: =D16/$D$10 -> 0.083844955 | U16: =E16/$E$10 -> 0.12662785
B17: Finance Costs | C17: =C16+1 -> 25 | D17: ='PL Notes 19-27'!C86 -> 2699 | E17: ='PL Notes 19-27'!D86 -> 763.08652 | F17: ='PL Notes 19-27'!E86 -> 38 | G17: =D13+D15 -> 15404.67 | Q17: Tomorrow | R17: =D21/10*12 -> -9048.288 | S17: =R17/1000 -> -9.048288 | T17: =D17/$D$10 -> 0.11374268 | U17: =E17/$E$10 -> 0.65388734
B18: Depreciation and Amortisation Expense | C18: =Input!D69 -> 3 | D18: ='PPE- note 3'!G17+'PPE- note 3'!G23+'PPE- note 3'!G27 -> 3180.683 | E18: =129491/100 -> 1294.91 | F18: ='PPE- note 3'!I141 -> 6 | G18: =G17*1000 -> 15404670 | Q18: Tomorrow | T18: =D18/$D$10 -> 0.13404202 | U18: =E18/$E$10 -> 1.1096058
B19: Other Expenses | C19: =C17+1 -> 26 | D19: ='PL Notes 19-27'!C111 -> 5883 | E19: ='PL Notes 19-27'!D111 -> 466 | F19: ='PL Notes 19-27'!E111 -> 38 | G19: 348000 | Q19: Navaz | R19: =D19*1000 -> 5883000 | S19: =D21+D18+D17 -> -1660.5569 | T19: =D19/$D$10 -> 0.24792448 | U19: =E19/$E$10 -> 0.39931448
B20: Total Expense (II) | D20: =SUM(D13:D19) -> 31269.24 | E20: =SUM(E13:E19) -> 3197.4612 | F20: =SUM(F17:F19) -> 82 | I20: PBT As per IND AS | J20: PBT As per IGAAP | K20: Difference | L20: Reco | M20: Head | N20: Remark | R20: -2.0562767e+08
A21: III | B21: (Loss) Before Tax (I-II) | D21: =D10-D20 -> -7540.24 | E21: =E10-E20 -> -2030.4612 | F21: =#REF!-F20 -> #REF! | G21: =D21+D17+D18 -> -1660.5569 | I21: =E21 -> -2030.4612 | J21: =487303222.278789/10^5 -> 4873.0322 | K21: =I21-J21 -> -6903.4934 | L21: ='TB BVS 31.3.23'!J173/10^5 -> 0 | M21: Employee Compensation - ESOP | N21: Not Considered in IGAAP | R21: 1.3109907e+08 | T21: =D21+S21 -> -7540.24
A22: IV | B22: Tax Expenses | L22: =5550219/10^5 -> 55.50219 | M22: Pharma Related Expenses Provision | N22: Not considered in IND AS | R22: =D26*1000 -> -5952240 | T22: =R22-S22 -> -5952240
B23: (a) Current Tax | C23: 16 | D23: =ROUND(SUMIF('TB BVS 31.03.26'!$E:$E,B23,'TB BVS 31.03.26'!$I:$I)/Input!$C$2,Input!$E$2) -> 0 | E23: 0 | F23: 0 | L23: =L22-L21 -> 55.50219 | R23: =D21+D18+D17 -> -1660.5569 | S23: =E21+E18+E17 -> 27.5353
B24: (b) Deferred Tax | C24: =BS!C16 -> 16 | D24: =ROUND(SUMIF('TB BVS 31.03.26'!$E:$E,B24,'TB BVS 31.03.26'!$I:$I)/Input!$C$2,Input!$E$2) -> -1588 | E24: =-142.606394191297/100 -> -1.4260639 | F24: =ROUND(SUMIF('TB BVS 31.3.22'!$E:$E,B24,'TB BVS 31.3.22'!$L:$L)/Input!$C$2,Input!$E$2) -> -1
B25: Total Tax Expenses | D25: =SUM(D23:D24) -> -1588 | E25: =SUM(E23:E24) -> -1.4260639 | F25: =SUM(F23:F24) -> -1 | R25: 1.847648e+08 | S25: =R25/1000 -> 184764.8
A26: V | B26: (Loss) for the Year (III-IV) | D26: =D21-D25 -> -5952.24 | E26: =E21-E25 -> -2029.0352 | F26: =F21-F25 -> #REF! | S26: =S25+D26 -> 178812.56
A28: VI | B28: Other Comprehensive Income
B29: (i) Item that will not be reclassified to profit or loss
B30: Remeasurement of defined benefit plans | C30: =C24 -> 16 | D30: =-ROUND(SUMIF('TB BVS 31.03.26'!$E:$E,B30,'TB BVS 31.03.26'!$I:$I)/Input!$C$2,Input!$E$2) -> 9 | E30: =ROUND(SUMIF('TB BVS 31.3.25'!$E:$E,B30,'TB BVS 31.3.25'!$I:$I)/Input!$C$2,Input!$E$2) -> 2
B31: Income tax relating to items that will not be reclassified to profit or loss | C31: =C30 -> 16 | D31: =ROUND(SUMIF('TB BVS 31.03.26'!$E:$E,B31,'TB BVS 31.03.26'!$I:$I)/Input!$C$2,Input!$E$2) -> -2 | E31: 0
B33: Other Comprehensive Income for the Year | D33: =SUM(D30:D32) -> 7 | E33: =SUM(E30:E32) -> 2 | F33: =F28 -> 0
B34: Total Comprehensive Income/(Loss) for the Year (V+VI) | D34: =D26+D33 -> -5945.24 | E34: =E26+E33 -> -2027.0352 | F34: =F26+F33 -> #REF!
A36: VII | B36: Earnings Per Share (Face Value of ₹ 10 each)
B37: - Basic & Diluted | C37: 27 | D37: ='PL Notes 19-27'!C120 -> -2082 | E37: ='PL Notes 19-27'!D120 -> -961 | F37: ='PL Notes 19-27'!E120 -> #REF!
A38: Corporate Information & Material Accounting Policies | C38: =BS!C62 -> 1 & 2
A39: The accompanying notes are integral part of the Financial Statements.
A40: As per our report of even date attached.
A42: =BS!$A$66 -> For B S R and Co | D42: =BS!D66 -> For and on behalf of Board of
A43: =BS!$A$67 -> Chartered Accountants | D43: =BS!D67 -> BVC Specialities Private Limited
A44: =BS!$A$68 -> Firm's Registration No: 128510W | D44: =BS!D68 -> CIN : U24230GJ2021PTC123855
A47: =BS!$A$71 -> Jeyur Shah | D47: =BS!D71 -> Shishir Srivastava | E47: =BS!E71 -> Shaju Ouseph Chazhoor
...

Sheet CFS Working
B1: Total Interest in Finance Cost
B2: - Preference shares | C2: ='PL Notes 19-27'!C83 -> 0
B3: Other Borrowing Cost | C3: ='PL Notes 19-27'!C84 -> 232
B4: Other Interest Expenses* | C4: ='PL Notes 19-27'!C85 -> 0
C5: =SUM(C2:C4) -> 232
B8: Interest Accrued
B9: - Preference shares | C9: =C2 -> 0 | E9: DTL >>> Other Equity
B10: Other Interest Expenses* | C10: =C4 -> 0 | E10: Provision other expe >>> Trade Payable

Sheet IT Computation_FY24
B2: Name : | C2: BVC Specialities Private Limited | E2: PAN : | F2: AAJCB9629E
B3: Address : | C3: 801 to 809, 824, 8th FLOOR, BLOCK 1, BUILDING 73, EST AVENUE, SARABHAI COMPOUND VADODARA - 390023 | E3: A.Y. : | F3: 2023 - 2024
E4: P.Y. : | F4: 2022 - 2023
B7: STATEMENT SHOWING COMPUTATION OF INCOME
B8: PARTICULARS | E8: Amt In INR | F8: Amt In INR
B10: I | C10: Income From Business
C11: Net Profit as per Statement of Profit and Loss before tax | F11: =PL!D21*1000 -> -7540240 | L11: =PL!F21*1000 -> #REF!
B13: Add: | C13: Items disallowed
C14: Expenditure relating to trading activities/Other disallowances | E14: 0
C15: Interest on late payment of TDS | E15: 0 | K15: ='TB BVS 31.3.22'!L23 -> 164
C16: Interest on MSME | E16: ='TB BVS 31.3.25'!G114 -> 0 | G16: =(+E16+E17+E26+E27)*17.16% -> -8487.336 | H16: =E16+E17+E18 -> 3180683
C17: Interest on borrowings measured at amortised cost - Preference Shares (notional) | E17: ='PL Notes 19-27'!$C$83*1000 -> 0 | H17: =H16*17.16% -> 545805.21 | K17: ='PL Notes 19-27'!$E$83*A1 -> 0
C18: Depreciation as per P&L | E18: =PL!D18*1000 -> 3180683 | G18: This is related to lease
C19: Miscellaneosus expenses | E19: ='PL Notes 19-27'!C109*1000*0 -> 0 | G19: 17.16
C20: Expenditure relating to lease (deferred) | E20: 0 | G20: =+E18+E24 -> 3227634 | K20: =PL!F18*A1 -> 0
C21: Expenditure relating to manufacturing (deferred) | E21: 0 | F21: =SUM(E14:E21) -> 3180683 | L21: =SUM(K14:K21) -> 164
B23: Less: | C23: Income considered under other head/ignored for tax
C24: Depreciation as per IT Act | E24: =-'IT Comp workings_FY24'!E21 -> 46950.993
C25: Capital gain on redemption of units of mutual fund | E25: ='TB BVS 31.3.25'!I72 -> 4679369.2 | G25: =+E25+E26 -> 4638309.2
C26: IND AS - Interest | E26: ='TB BVS 31.3.25'!I73 -> -41060
C27: 35D - Preliminary expenses (3rd year) | E27: -8400
C28: Interest Income HDFC BANK LIMITED - as per 26AS | E28: =-'PL Notes 19-27'!C28*1000 -> -4000
C29: Interest Income AXIS BANK LIMITED - as per 26AS
C30: Leasehold amortisation | E30: =-'IT Comp workings_FY24'!C62 -> -17876.795
F31: =SUM(E24:E31) -> 4654983.4
C33: Income from business / profession | F33: =SUM(F11:F31) -> 295426.5
B35: III | C35: Income From Capital Gains
C36: Gain redemption of units of mutual fund
C37: Sale consideration | E37: ='IT Comp workings_FY24'!D30 -> 13741618
C38: Less:- Cost of acquisition | F38: =E37-E38 -> 13741618
C40: Gain redemption of units of Debt mutual fund | E40: ='IT Comp workings_FY24'!D28+'IT Comp workings_FY24'!D34 -> 3479670.3
C41: Sale consideration | F41: =E40-E41 -> 3479670.3
C42: Less:- Cost of acquisition
B44: III | C44: Income From Other Sources
C45: Interest Income | D45: =E30*0 -> 0
C46: ICD Interest (BVO) | D46: =12674410.7755109 -> 12674411 | G46: Krishna to update
C47: Interest Income HDFC BANK LIMITED - as per 26AS | D47: =91096*0 -> 0
C48: Interest Income AXIS BANK LIMITED - as per 26AS | D48: =1532699*0-E28 -> 4000
D49: =SUM(D45:D48) -> 12678411
D50: 11686977 | E50: =D49-D50 -> 991433.8 | F50: =SUM(E45:E50) -> 991433.8 | G50: =F50*17.16% -> 170130.04 | H50: =D46-D50 -> 987433.8
...

Sheet IT Comp workings_FY24
A1: IT Computation workings
A4: Earlier disallowances
A5: AY 2023-24
A6: Expenditure deferred relating to manufacturing | B6: 4519228
A7: Expenditure deferred relating to leasehold rights amortisation | B7: 1752790 | C7: =SUM(B6:B7) -> 6272018
A10: AY 2022-23
A11: Expenditure deferred relating to manufacturing | B11: 3321551
A12: Expenditure deferred relating to leasehold rights amortisation | B12: 3954723 | C12: =SUM(B11:B12) -> 7276274
A16: Particulars | B16: Additions during FY 2023-24 | C16: Allocation of deferred manufacturing exp | D16: Total | E16: Depreciation | F16: ITWDV | G16: Book WDV
A17: Plant and machinery | B17: ='PPE- note 3'!C94*1000 -> -60000 | C17: =$C$21/$B$21*B17 -> -434220.98 | D17: =B17+C17 -> -494220.98 | E17: =D17*15%/2 -> -37066.574 | F17: =D17-E17 -> -457154.41 | G17: ='PPE- note 3'!E94*1000 -> -60000 | H17: =F17-G17 -> -397154.41
A18: Building | B18: ='PPE- note 3'!C93*1000 -> 0 | C18: =$C$21/$B$21*B18 -> 0 | D18: =B18+C18 -> 0 | E18: =D18*10%/2 -> 0 | F18: =D18-E18 -> 0 | G18: ='PPE- note 3'!E93*1000 -> 0 | H18: =F18-G18 -> 0
A19: Computers | B19: ='PPE- note 3'!C95*1000 -> -6000 | C19: =$C$21/$B$21*B19 -> -43422.098 | D19: =B19+C19 -> -49422.098 | E19: =D19*40%/2 -> -9884.4196 | F19: =D19-E19 -> -39537.678 | G19: ='PPE- note 3'!E95*1000 -> -6000 | H19: =F19-G19 -> -33537.678
A20: CWIP | B20: =BS!D10*1000 -> 1149427 | C20: =$C$21/$B$21*B20 -> 8318422.1 | D20: =B20+C20 -> 9467849.1 | F20: =SUM(F17:F19) -> -496692.09 | G20: =SUM(G17:G19) -> -66000 | H20: =SUM(H17:H19) -> -430692.09 | I20: =H20*25.168% -> -108396.58
B21: =SUM(B17:B20) -> 1083427 | C21: =B11+B6 -> 7840779 | D21: =B21+C21 -> 8924206 | E21: =SUM(E17:E20) -> -46950.993 | F21: =-(F17+F19) -> 496692.09 | G21: =('PPE- note 3'!J96-'PPE- note 3'!J92)*1000 -> -149000 | H21: =G21+F21 -> 347692.09 | I21: =H21*17.168% -> 59691.777
F22: =-F21*17.168% -> -85272.097 | G22: =-G21*17.168% -> 25580.32 | H22: =F22+G22 -> -59691.777
A25: Capital gains
A26: HDFC Overnight Fund - Direct Plan - Growth Option | B26: 875943.49 | D26: =B26+C26 -> 875943.49
A27: HDFC Liquid Fund-Direct Plan-Growth Option Cash, | B27: 2658651.4 | D27: =B27+C27 -> 2658651.4
B28: =SUM(B26:B27) -> 3534594.9 | D28: =SUM(D26:D27) -> 3534594.9
A30: HDFC Arbitrage Fund - Wholesale Plan - Growth - Direct Plan Arbitrage Fund, | B30: 13736481 | C30: =250+500+1000+500+1000+500+1387 -> 5137 | D30: =B30+C30 -> 13741618
B32: =B30+B28 -> 17271075 | D32: =D30+D28 -> 17276212
D33: =-'[12]TB BVS 31.3.24'!I73 -> 17331137
D34: =D32-D33 -> -54924.59 | E34: diff
A38: Leasehold
A39: Expenditure deferred relating to leasehold rights amortisation (AY 2023-24)
A40: Amortisation | B40: 1752790
A43: Expenditure deferred relating to leasehold rights amortisation (AY 2022-23)
A44: Int on borrowing | B44: 3344847.9 | C44: =B44 -> 3344847.9
A45: Amortisation | B45: 609875
A49: Leasehold land
A50: Cost of acquisition | B50: ='PPE- note 3'!E100*1000 -> 3244000 | C50: =B50 -> 3244000
C53: =SUM(C40:C52) -> 6588847.9
A55: Lease period
A56: 42789
A57: =(99*365)+A56 -> 78924 | B57: =(A57-A56)/365 -> 99
A58: Balance lease period
A59: 45292
A60: =A57 -> 78924 | B60: =(A60-A59)/365 -> 92.142466 | C60: =C53/B60/12 -> 5958.9317 | D60: Per month
A62: Jan 24 to March 24 | C62: =C60*3 -> 17876.795

Sheet Cash Flow_FY26
A1: =Input!$B$1 -> BVC Specialities Private Limited
A2: Statement of Cash Flows for the Year Ended 31 March 2026
D3: =Input!$D$2 -> (₹ in Lakh) | E3: =Input!$D$2 -> (₹ in Lakh)
A4: Particulars | C4: Year Ended | D4: Year Ended | E4: Year Ended
C5: =PL!D5 -> 31 March 2026 | D5: =PL!E5 -> 31 March 2025 | E5: =Input!$C$6 -> 31 March 2022
A6: Cash Flow from Operating Activities
A7: (Loss) before Tax | C7: =PL!D21 -> -7540.24 | D7: =PL!E21 -> -2030.4612 | E7: -8360 | I7: 10669.917 | J7: =C7-I7 -> -18210.157
A8: Adjustments for: | J8: =C8-I8 -> 0
A9: Depreciation and amortisation | C9: =PL!D18 -> 3180.683 | D9: =PL!E18 -> 1294.91 | E9: =PL!F18 -> 6 | I9: 3767 | J9: =C9-I9 -> -586.31698
A10: Inventory Written Off | C10: ='PL Notes 19-27'!C102 -> 13 | D10: 0
A11: Interest Income | C11: =-'PL Notes 19-27'!C28-'PL Notes 19-27'!C29 -> -23 | D11: =-'PL Notes 19-27'!D28-'PL Notes 19-27'!D29 -> -20
A12: Profit on sale of mutual fund | C12: =-'PL Notes 19-27'!C30 -> 0 | D12: =-'PL Notes 19-27'!D30 -> -49
A13: Unrealized foreign exchange loss/ (gain) | C13: =C147 -> -72.325743 | D13: 0
A14: Allowance for expected credit loss on trade receivables | C14: ='PL Notes 19-27'!C108 -> 15 | D14: 0
A15: Finance costs | C15: =PL!D17 -> 2699 | D15: =PL!E17 -> 763.08652 | E15: =PL!F17 -> 38 | I15: 3744 | J15: =C15-I15 -> -1045
C16: =SUM(C9:C15)+C7 -> -1727.8827 | D16: =SUM(D9:D15)+D7 -> -41.4647 | E16: =SUM(E9:E15)+E7 -> -8316 | I16: 18180.917 | J16: =C16-I16 -> -19908.8
J17: =C17-I17 -> 0
A18: Changes in working capital: | J18: =C18-I18 -> 0
A19: (Increase)/Decrease in Trade Receivable | C19: =BS!H24-C145-C14 -> -2476.2564 | D19: -397.74 | I19: -5611 | J19: =C19-I19 -> 3134.7436
A20: (Increase)/Decrease in Inventory | C20: =BS!H22-C10 -> -5840 | D20: -797.4 | I20: -1391 | J20: =C20-I20 -> -4449
A21: (Increase)/Decrease in Other Financial Assets | C21: =BS!H15 -> 45 | D21: 4.28 | I21: 745060 | J21: =C21-I21 -> -745015
A22: (Increase)/Decrease in Other Non-Financial Assets | C22: =+BS!H29+BS!H18+H34 -> -856 | D22: -1277.86 | E22: =F132-E132 -> -296 | I22: -462302 | J22: =C22-I22 -> 461446
A23: Increase/(Decrease) in Trade payable | C23: =BS!H53+BS!H54-C144-2 -> 8076.027 | D23: 1659.3 | E23: =(E134-F134)+E135 -> 14 | I23: 8661 | J23: =C23-I23 -> -584.97303
A24: Increase/(Decrease) in Employee Benefit Liabilities | C24: =BS!H45+BS!H58+PL!D30+PL!D31 -> 53 | D24: 22.74
A25: Increase/(Decrease) in Other Financial Liabilities | C25: =BS!H55 -> -2063 | D25: 48.56
A26: Increase/(Decrease) in Non-Financial Liabilities | C26: =BS!H56+BS!H57-'BS Notes 3-18'!O468 -> 2047 | D26: -23.2 | E26: =(E139-F139)-1 -> -1 | I26: 6029 | J26: =C26-I26 -> -3982
A27: Cash used in Operations | C27: =C16+SUM(C19:C26) -> -2742.1121 | D27: =D16+SUM(D19:D26) -> -802.7847 | E27: =E16+SUM(E22:E26) -> -8599 | I27: 308626.92 | J27: =C27-I27 -> -311369.03
A28: Income Taxes Paid | C28: =BS!H16+BS!H17-PL!D25 -> 9.1153389 | D28: 0 | H28: =C28 -> 9.1153389 | I28: -26514.917 | J28: =C28-I28 -> 26524.033
A29: Net Cash Flow from Operating Activities (A) | C29: =C27+C28 -> -2732.9967 | D29: =D27 -> -802.7847 | E29: =E27 -> -8599 | I29: 282112 | J29: =C29-I29 -> -284845
J30: =C30-I30 -> 0
A31: Cash Flow from Investing Activities | J31: =C31-I31 -> 0
A32: Acquisition of Property, Plant and Equipment and Change in Capital Work in Progress | C32: =BS!H8+BS!H9+BS!H10+BS!H11-C9+'BS Notes 3-18'!O468 -> -3424.4646 | D32: -23239.35 | E32: ='PPE- note 3'!C140 -> 1652 | F32: =1846-C9 -> -1334.683 | I32: -3316196 | J32: =C32-I32 -> 3312771.5
A33: Acquisition of Investments | C33: =-F34 -> -94 | D33: 0 | F33: JSW | I33: -292929 | J33: =C33-I33 -> 292835
A34: Investment in fixed deposit and bank balances other than cash and cash equivalent | C34: =BS!H28 -> -54 | D34: 0 | F34: 94 | G34: 1 | H34: 79 | I34: -2637 | J34: =C34-I34 -> 2583
A35: Interest Received | C35: ='PL Notes 19-27'!C28+'PL Notes 19-27'!C29 -> 23 | D35: 20.08 | I35: =F34+G34-H34 -> 16
A36: Proceeds from sale of mutual fund | C36: 0 | D36: 5548.6245
A37: Investment in mutual fund | C37: 0 | D37: -5499.725
A38: Loan given to fellow subsidiary | C38: 0 | D38: -110.95979
A39: Repayment of loan by fellow subsidiary | C39: 0 | D39: 3040.2498
A40: Net Cash Flow from Investing Activities (B) | C40: =SUM(C32:C39) -> -3549.4646 | D40: =SUM(D32:D39) -> -20241.081 | E40: =-SUM(E32:E32) -> -1652 | I40: -3611762 | J40: =C40-I40 -> 3608212.5
...

Sheet SOCIE
A1: =Input!$B$1 -> BVC Specialities Private Limited
A2: Statement of Changes in Equity (SOCIE) for the Year Ended on 31 March 2026
A5: (A) Equity Share Capital | E5: =Input!$D$2 -> (₹ in Lakh)
A6: Particulars | D6: As at 31 March 2026 | E6: As at 31 March 2025
A7: Balance at the beginning of the reporting year | D7: =E9 -> 13.6597 | E7: =1072/100 -> 10.72
A8: Changes in equity share capital during the year | D8: ='BS Notes 3-18'!G146-SOCIE!D7 -> 2.3192 | E8: =293.97/100 -> 2.9397
A9: Balance at the end of the reporting year | D9: =SUM(D7:D8) -> 15.9789 | E9: =SUM(E7:E8) -> 13.6597
A11: (B) Instruments entirely equity in nature
A12: Compulsory Convertible Preference Shares - Share Application Money Pending Allotment
A13: Particulars | D13: =CONCATENATE("As at ",Input!$C$4) -> As at 31 March 2024 | E13: =CONCATENATE("As at ",Input!$C$5) -> As at 31 March 2023
A14: Balance at the beginning of the reporting period
A15: Addition in compulsorily convertible preference shares during the year
A16: Balance at the end of the reporting period
A18: (B) Instrument Entirely Equity in Nature
A19: Particulars | D19: =D6 -> As at 31 March 2026 | E19: =E6 -> As at 31 March 2025
A20: Balance at the beginning of the reporting year | D20: =E22 -> 9.1868 | E20: ='BS Notes 3-18'!H179 -> 4.4097
A21: Changes in instruments entirely equity in nature during the year | D21: ='BS Notes 3-18'!G187 -> 0 | E21: ='BS Notes 3-18'!H187 -> 4.7771
A22: Balance at the end of the reporting year | D22: =SUM(D20:D21) -> 9.1868 | E22: =SUM(E20:E21) -> 9.1868
A24: (C) Other Equity
A25: Particulars | B25: Attributable to the equity shareholders | E25: Total Other Equity
B26: Equity component of compound financial instrument | C26: Reserve and Surplus
C27: Securities Premium | D27: Retained earnings
A28: Loss for the year | B28: 0 | C28: 0 | D28: -82.88 | E28: =SUM(B28:D28) -> -82.88
A29: Total comprehensive income for the year | B29: =SUM(B28) -> 0 | C29: =SUM(C28) -> 0 | D29: =SUM(D28) -> -82.88 | E29: =SUM(E28) -> -82.88
A30: Issue of Optionally Convertible Preference Shares | B30: ='BS Notes 3-18'!I231 -> 1250 | C30: 0 | D30: 0 | E30: =SUM(B30:D30) -> 1250
A31: =CONCATENATE("Balance as at ",Input!$C$6) -> Balance as at 31 March 2022 | B31: =B29+B30 -> 1250 | C31: =C29+C30 -> 0 | D31: =D29+D30 -> -82.88 | E31: =E29+E30 -> 1167.12 | G31: =BS!F37-SOCIE!E31 -> #REF! | H31: Check
A33: Balance as at 1 April 2022 | B33: =B31 -> 1250 | C33: =C31 -> 0 | D33: =D31 -> -82.88 | E33: =SUM(B33:D33) -> 1167.12
A34: Loss for the year | B34: 0 | C34: 0 | D34: -95.26 | E34: =SUM(B34:D34) -> -95.26
A35: Total comprehensive income for the year | B35: =SUM(B34:B34) -> 0 | C35: =SUM(C34:C34) -> 0 | D35: =SUM(D34:D34) -> -95.26 | E35: =SUM(E34:E34) -> -95.26
A36: Balance as at 31 March 2023 | B36: =B33+B35 -> 1250 | C36: =C33+C35 -> 0 | D36: =D33+D35 -> -178.14 | E36: =E33+E35 -> 1071.86 | G36: =BS!E37-SOCIE!E36 -> 25683.576 | H36: Check
A37: Profit (Loss) for the year | B37: 0 | C37: 0 | D37: =7151.5736058087/100 -> 71.515736 | E37: =SUM(B37:D37) -> 71.515736
A38: Contribution by and distribution to owners | B38: 0 | C38: 0 | D38: 0 | E38: =SUM(B38:D38) -> 0
A39: Redemption of compound financial instruments | B39: ='BS Notes 3-18'!H231 -> -1250 | C39: =204224/100 -> 2042.24 | D39: =386.61503/100 -> 3.8661503 | E39: =SUM(B39:D39) -> 796.10615
A40: Total contribution by and distribution to owners | B40: =SUM(B37:B39) -> -1250 | C40: =SUM(C37:C39) -> 2042.24 | D40: =SUM(D37:D39) -> 75.381886 | E40: =SUM(E37:E39) -> 867.62189
A41: Balance as at 31 March 2024 | B41: =B36+B40 -> 0 | C41: ='BS Notes 3-18'!H235 -> 12037.707 | D41: =D36+D40 -> -102.75811 | E41: =C41+D41 -> 11934.949 | J41: ='BS Notes 3-18'!H227-E41 -> 14820.488
A42: (Loss) for the year | B42: 0 | C42: 0 | D42: =PL!E26 -> -2029.0352 | E42: =SUM(B42:D42) -> -2029.0352
A43: Addition during the year | B43: ='BS Notes 3-18'!G231 -> 0 | C43: 0 | D43: 0 | E43: =SUM(B43:D43) -> 0
A44: Other comprehensive Income for the year | B44: 0 | C44: 0 | D44: =PL!E30+PL!E31 -> 2 | E44: =SUM(B44:D44) -> 2
A45: Total comprehensive income for the year | B45: =SUM(B42:B43) -> 0 | C45: =SUM(C42:C43) -> 0 | D45: =SUM(D42:D44) -> -2027.0352 | E45: =SUM(E42:E44) -> -2027.0352
A47: Transactions with owners of the Company
...

Sheet PPE- note 3
A1: =BS!A1 -> BVC Specialities Private Limited
