Workbook
Name \0: #REF!
Name \A: #REF!
Name \B: #REF!
Name \C: #REF!
Name \D: #REF!
Name \S: #REF!
Name \Z: #REF!
Name _________DAT1: [4]Exp.!#REF!
Name _________DAT10: #REF!
Name _________DAT11: #REF!
Name _________DAT12: #REF!
Name _________DAT13: #REF!
Name _________DAT14: #REF!
Name _________DAT15: #REF!
Name _________DAT16: #REF!
Name _________DAT2: [4]Exp.!#REF!
Name _________DAT3: [4]Exp.!#REF!
Name _________DAT4: [4]Exp.!#REF!
Name _________DAT5: [4]Exp.!#REF!
Name _________DAT6: [4]Exp.!#REF!
Name _________DAT7: [4]Exp.!#REF!
Name _________DAT8: [4]Exp.!#REF!
Name _________DAT9: #REF!
Name ________DAT1: [4]Exp.!#REF!
Name ________DAT10: #REF!
Name ________DAT11: #REF!
Name ________DAT12: #REF!
Name ________DAT13: #REF!
Name ________DAT14: #REF!
Name ________DAT15: #REF!
Name ________DAT16: #REF!
Name ________DAT2: [4]Exp.!#REF!
Name ________DAT3: [4]Exp.!#REF!
Name ________DAT4: [4]Exp.!#REF!
Name ________DAT5: [4]Exp.!#REF!
Name ________DAT6: [4]Exp.!#REF!
Name ________DAT7: [4]Exp.!#REF!
Name ________DAT8: [4]Exp.!#REF!
Name ________DAT9: #REF!
Name _______DAT1: [4]Exp.!#REF!
Name _______DAT10: #REF!
Name _______DAT11: #REF!
Name _______DAT12: #REF!
Name _______DAT13: #REF!
Name _______DAT14: #REF!
Name _______DAT15: #REF!
Name _______DAT16: #REF!
Name _______DAT2: [4]Exp.!#REF!
Name _______DAT3: [4]Exp.!#REF!
Name _______DAT4: [4]Exp.!#REF!
Name _______DAT5: [4]Exp.!#REF!
Name _______DAT6: [4]Exp.!#REF!
Name _______DAT7: [4]Exp.!#REF!
Name _______DAT8: [4]Exp.!#REF!
Name _______DAT9: #REF!
Name ______DAT1: [4]Exp.!#REF!
Name ______DAT10: #REF!
Name ______DAT11: #REF!
Name ______DAT12: #REF!
Name ______DAT13: #REF!

Sheet BS
A1: L&T ELECTROLYSERS LIMITED
A2: Balance sheet as at March 31, 2026
H4: ( Amt in Rs.)
A5: Particulars | D5: Note No. | E5: As at March 31, 2026 | G5: As at March 31, 2025
A7: ASSETS
A8: (1) Non current assets
B9: a) Property, plant and equipment | D9: 2 | E9: =' 2'!J17 -> 0 | G9: =' 2'!K17 -> 0
B10: b) Capital work-in-progress | D10: 3 | E10: ='3 CWIP'!F13 -> 0 | G10: ='3 CWIP'!B13 -> 0
B11: c) Other intangible assets | D11: 4 | E11: =' 4'!J13 -> 0 | G11: =' 4'!K13 -> 0
B12: d) Intangible assets under development | D12: 5 | E12: ='5'!B11 -> 0 | G12: ='5'!C11 -> 0
B13: e) Right-of-use assets | D13: 2A | E13: =' 2'!J27 -> 0 | G13: =' 2'!K27 -> 0
B14: f) Other non current assets | E14: =AI66 -> 0 | G14: =AP33+AP66+AP67 -> 0
F15: =SUM(E9:E14) -> 0 | H15: =SUM(G9:G14) -> 0
A17: (2) Current assets
B18: a) Inventories | D18: 6 | E18: ='6'!B14 -> 0 | G18: ='6'!C14 -> 0
B19: b) Financial assets
B20: i) Investment | D20: 7 | E20: ='7'!B10 -> 0 | G20: ='7'!C10 -> 0
B21: ii) Trade receivables | D21: 8 | E21: ='8'!B10 -> 0 | G21: ='8'!C10 -> 0
B22: iii) Cash and cash equivalents | D22: 9 | E22: ='9'!B11 -> 0 | G22: ='9'!C11 -> 0
B23: iv) Other current financial assets | D23: 10 | E23: ='10'!B13 -> 0 | G23: ='10'!C13 -> 0
B24: c) Other current assets | D24: 11 | E24: ='11'!B17 -> 0 | G24: ='11'!C17 -> 0
F25: =SUM(E18:E24) -> 0 | H25: =SUM(G18:G24) -> 0
A27: Total Assets | F27: =F15+F25 -> 0 | H27: =H15+H25 -> 0
A29: EQUITY AND LIABILITIES
A30: (1) Equity
B31: a) Equity share capital | D31: 12 | E31: ='12'!B16 -> 0 | G31: ='12'!C12 -> 0
B32: b) Other equity | D32: 13 | E32: ='13'!E14 -> 0 | G32: ='13'!E26 -> 0
F33: =SUM(E31:E32) -> 0 | H33: =SUM(G31:G32) -> 0
A35: (2) Non current liabilities
B36: a) Financial liabilities
B37: (i) Lease liability | E37: =-AI118-E42 -> 0 | G37: 0
F38: =E37 -> 0 | H38: =SUM(G36:G37) -> 0
A39: (3) Current liabilities
B40: a) Financial liabilities
B41: i) Borrowings | D41: 14 | E41: ='14'!B12 -> 0 | G41: ='14'!C12 -> 0
B42: ii) Lease liability | E42: =AI118 -> 0 | G42: 0
B43: iii) Trade payables | D43: 15 | E43: ='15'!B12 -> 0 | G43: ='15'!C12 -> 0
B44: iv) Other financial liabilities | D44: 16 | E44: ='16'!B13 -> 0 | G44: ='16'!C13 -> 0
B45: b) Other current liabilities | D45: 17 | E45: ='17'!B19 -> 0 | G45: ='17'!C19 -> 0
B46: c) Provision | D46: 18 | E46: ='18'!B12 -> 0 | G46: ='18'!C12 -> 0
...

Sheet PL
A1: L&T ELECTROLYSERS LIMITED
A2: Statement of profit and loss for the year ended March 31, 2026
A4: Particulars | C4: Note No. | D4: Year ended March 31, 2026 | F4: Year ended March 31, 2025
A5: REVENUE
B6: Revenue from operations | C6: 19 | E6: ='19'!B10 -> 0 | G6: ='19'!C8 -> 0
B7: Other income | C7: 20 | E7: ='20'!B15 -> 0 | G7: ='20'!C15 -> 0
B8: TOTAL INCOME | E8: =SUM(E6:E7) -> 0 | G8: =SUM(G6:G7) -> 0
A10: EXPENSES
B11: Cost of raw materials and components consumed | C11: 21a | D11: ='21'!B18 -> 0 | F11: ='21'!C18 -> 0
B12: Manufacturing and other operating expenses | C12: 21b | D12: ='21'!B33 -> 0 | F12: =SUM('21'!C33) -> 0
B13: Change in inventories of finished goods and work - in - progress | C13: 21c | D13: ='21'!B51 -> 0 | E13: =SUM(D11:D13) -> 0 | F13: =SUM('21'!C51) -> 0 | G13: =SUM(F11:F13) -> 0
B14: Employee benefit expenses | C14: 22 | E14: ='22'!B13 -> 0 | G14: ='22'!C13 -> 0
B15: Selling, administration and other expenses | C15: 23 | E15: ='23'!B29 -> 0 | G15: ='23'!C29 -> 0
B16: Finance costs | C16: 24 | E16: ='24'!B14 -> 0 | G16: ='24'!C14 -> 0
B17: Depreciation and amortization | C17: 25 | E17: ='25'!B12 -> 0 | G17: ='25'!C12 -> 0
B18: TOTAL EXPENSES | E18: =SUM(E11:E17) -> 0 | G18: =SUM(G11:G17) -> 0
A20: Profit before exceptional items and taxes | E20: =E8-E18 -> 0 | G20: =G8-G18 -> 0
A21: Exceptional item | C21: 22 A | E21: ='22'!B21 -> 0 | G21: 0
A22: Profit / (loss) before tax | E22: =E20-E21 -> 0 | G22: =+G8-G18 -> 0
A24: Tax expense : -
B25: i) Current tax
B26: ii) Deferred tax
B27: PROFIT / (LOSS) AFTER TAX FOR THE YEAR | E27: =E22 -> 0 | G27: =G22 -> 0
A29: Other comprehensive income
B30: Items that will not be reclassified subsequently to profit/loss Gain/(loss) on remeasurements of the defined benefits plan | E30: =(AP6-AI6) -> 0 | G30: 0
B31: Items that will be reclassified subsequently to profit/loss - Effective portion of gains/(losses) on hedging instruments in cash flow hedge
B32: TOTAL COMPREHENSIVE INCOME FOR THE YEAR | E32: =E27+E30 -> 0 | G32: =G27+G30 -> 0
A34: Earnings per equity share (basic and diluted) (₹) | C34: 26 | E34: ='26'!B11 -> #DIV/0! | G34: ='26'!C11 -> #DIV/0!
A35: Face value per equity share of ₹ 10 each
A37: Material accounting policies | C37: 1
A38: Notes forming parts of financial statements | C38: =BS!D51 -> 2 - 43
A40: =BS!A53 -> As per our report attached | D40: For and on behalf of the Board of Directors of
A41: =BS!A54 -> _______________ | D41: L&T Electrolysers Limited
A42: =BS!A55 -> Chartered Accountants
A43: =BS!A56 -> Firm's registration no. ______
A47: =BS!A60 -> Auditor | D47: =BS!E60 -> Director1 | F47: =BS!G60 -> Director2
A48: =BS!A61 -> Partner | D48: =BS!E61 -> Director | F48: =BS!G61 -> Director
A49: =BS!A62 -> Membership no. | D49: =BS!E62 -> DIN : | F49: =BS!G62 -> DIN :
A50: =BS!A63 -> Place : | D50: =BS!E63 -> Place : | F50: =BS!G63 -> Place :
A51: =BS!A64 -> Date : | D51: =BS!E64 -> Date : | F51: =BS!G64 -> Date :
...

Sheet SOCE
A1: =PL!A1 -> L&T ELECTROLYSERS LIMITED
A2: Statement of changes in equity for the year ended March 31, 2026
A4: A. Equity Share Capital
F6: ( Amt in Rs.)
A7: Particulars | B7: Balance as on 01 April 2025 | C7: Changes in the Equity Share Capital due to prior period errors | D7: Restated Balance as on 01 April 2025 | E7: Changes in the Equity Share Capital during the Reporting Period | F7: Balance at end of the Current Reporting Period (As at March 31, 2026)
A8: Equity Share Capital | B8: =F12 -> 0 | C8: 0 | D8: =B8+C8 -> 0 | E8: ='12'!B25*10 -> 0 | F8: =SUM(D8:E8) -> 0
F10: =F6 -> ( Amt in Rs.)
A11: Particulars | B11: Balance as on 01 April 2024 | C11: Changes in the Equity Share Capital due to prior period errors | D11: Restated Balance as on 01 April 2024 | E11: Changes in the Equity Share Capital during the year | F11: Balance at end of March 31, 2025
A12: Equity Share Capital | B12: 0 | C12: 0 | D12: =B12+C12 -> 0 | E12: 0 | F12: =SUM(D12:E12) -> 0
A15: B. Other Equity
F17: =F10 -> ( Amt in Rs.)
A18: Particulars | D18: Reserves and Surplus | F18: Equity Instruments through Other Comprehensive Income | G18: Other items of other Comprehensive income
D19: Securities premium Reserve | E19: Retained Earnings
A20: =B7 -> Balance as on 01 April 2025 | D20: 0 | E20: 0 | G20: 0
A21: Total Comprehnsive Income for the Current Year | D21: 0 | E21: ='[1]2'!#REF! -> #REF! | F21: 0 | G21: 0
A22: Dividend | D22: 0 | E22: 0 | F22: 0 | G22: 0
A23: Transfer to Retained Earning | D23: 0 | E23: =+E21-E22 -> #REF! | F23: =+F21-F22 -> 0 | G23: =+G21-G22 -> 0
A24: Any other Change | D24: 0
A25: Remeasurement of Defined Benefit Plan (Net of Tax) | D25: 0 | E25: 0 | G25: 0
A26: Equity Instrument fair value through Other Comprehensive Income (Net of Tax) | D26: 0 | E26: 0 | G26: 0
A27: Fair Valuation of Preferene Share | D27: 0 | E27: 0
A28: =F7 -> Balance at end of the Current Reporting Period (As at March 31, 2026) | D28: =SUM(D20:D25) -> 0 | E28: =+#REF!+E23+E25+E26+E27+E22 -> #REF! | G28: =+#REF!+G23+G25+G26+G27 -> #REF!
A30: Particulars | D30: Other Comprehensive Income | E30: Reserves and Surplus | G30: Total Equity
E31: Securities premium | F31: Retained Earnings
A32: Balance as on 01 April 2025 | D32: =D49 -> 0 | E32: 0 | F32: =F49 -> 0 | G32: =SUM(D32:F32) -> 0
A33: Profit for the period | D33: 0 | E33: 0 | F33: =PL!E27 -> 0 | G33: =SUM(D33:F33) -> 0
A34: Any other Changes | D34: 0 | G34: =SUM(D34:F34) -> 0
A35: Remeasurement of Defined Benefit Plan (Net of Tax) | D35: 0 | E35: 0 | F35: 0 | G35: =SUM(D35:F35) -> 0
A36: Equity Instrument fair value through Other Comprehensive Income (Net of Tax) | D36: =PL!E30 -> 0 | E36: 0 | F36: 0 | G36: =SUM(D36:F36) -> 0
A37: Fair Valuation of Preferene Share | D37: 0 | E37: 0 | F37: 0 | G37: =SUM(D37:F37) -> 0
A38: Balance as on 31 March, 2026 | D38: =SUM(D32:D37) -> 0 | E38: =SUM(E32:E37) -> 0 | F38: =SUM(F32:F37) -> 0 | G38: =SUM(D38:F38) -> 0
G40: =F17 -> ( Amt in Rs.)
A41: Particulars | D41: Other Comprehensive Income | E41: Reserves and Surplus | G41: Total Equity
E42: Securities premium | F42: Retained Earnings
A43: Balance as on 01 April 2024 | D43: 0 | E43: 0 | F43: 0 | G43: =SUM(D43:F43) -> 0
A44: Profit for the year | D44: 0 | E44: 0 | F44: =PL!G27 -> 0 | G44: =SUM(D44:F44) -> 0
A45: Any other Changes | D45: 0 | G45: =SUM(D45:F45) -> 0
A46: Remeasurement of Defined Benefit Plan (Net of Tax) | D46: 0 | E46: 0 | F46: 0 | G46: 0
A47: Equity Instrument fair value through Other Comprehensive Income (Net of Tax) | D47: =PL!G30 -> 0 | E47: 0 | F47: 0 | G47: =SUM(D47:F47) -> 0
A48: Fair Valuation of Preferene Share | D48: 0 | E48: 0 | F48: 0 | G48: =SUM(D48:F48) -> 0
...

Sheet CashFlow
B1: L&T ELECTROLYSERS LIMITED
B2: Cash Flow Statement for the year ended March 31, 2026
D3: =BS!H4 -> ( Amt in Rs.)
A4: Particulars | C4: Year ended March 31, 2026 | D4: Year ended March 31, 2025
A5: A. | B5: Cash flows from operating activities :-
B6: Net profit before tax and extraordinary items | C6: =PL!E20 -> 0 | D6: =PL!G20 -> 0
B7: Adjustments for :
B8: Less: Gain/ (Loss) on Sale of investment | C8: =-'20'!B9 -> 0 | D8: 0
B9: Less: Gain on de-recoginition of ROU | C9: =-'20'!B12 -> 0
B10: Less : Other comprehensive income
B11: Less: interest income | C11: 0
B12: Add: Interest expense | C12: ='24'!B14 -> 0 | D12: 0
B13: Add: Depreciation and amortisation | C13: 0 | D13: 0
B14: Add: Interest on lease liability
B15: Add: Exceptional Items
B16: Operating profit before working capital changes | C16: =SUM(C6:C15) -> 0 | D16: =SUM(D6:D13) -> 0
B17: Adjustments for :
B18: (Increase) / Decrease in current assets | C18: 0 | D18: 0
B19: (Increase) / Decrease in non-current assets | D19: 0
B20: (Increase) / Decrease in Inventories | C20: 0 | D20: 0
B21: Increase / (Decrease) in current liabilities | C21: 0 | D21: =+PL!G30+PL!G30 -> 0
B22: Cash generated from operations | C22: =SUM(C16:C21) -> 0 | D22: =SUM(D16:D21) -> 0
B23: Direct taxes refund / (paid) | C23: 0 | D23: 0
B24: Net cash from/(used in) operating activities (A) | C24: =C22+C23 -> 0 | D24: =SUM(D16:D21) -> 0
A26: B. | B26: Cash flows from investing activities:
B27: Purchase of Property, Plant & Equipment & Capital work in progress | C27: 0 | D27: 0
B28: Purchase of Intangible assets | C28: 0 | D28: 0
B29: Interest on investments | C29: 0 | D29: 0
B30: Investments in inter corporate deposits | C30: 0 | D30: 0
B31: Investment/ redemption of mutual funds | C31: 0 | D31: 0
B32: Net Cash used in investing activities (B) | C32: =SUM(C27:C31) -> 0 | D32: =SUM(D27:D31) -> 0
A34: C. | B34: Cash flows from financing activities:
B35: Proceeds from issue of share capital | C35: 0 | D35: 0
B36: Proceeds/ (payments) from/(to) unsecured loan | C36: 0 | D36: 0
B37: Overdraft facility availed from bank | C37: =BS!E41-BS!G41 -> 0 | D37: 0
B38: Interest paid | C38: 0 | D38: 0
B39: Interest paid on lease liability | C39: 0
B40: Principal payment of lease liability | C40: =BS!E37+BS!E42-BS!G37-BS!G42 -> 0 | D40: 0
B41: Net cash (used in)/flows from financing activities (C) | C41: =SUM(C35:C40) -> 0 | D41: =SUM(D35:D40) -> 0
B43: Net (decrease)/ increase in cash and cash equivalents (A+B+C) | C43: =C24+C32+C41 -> 0 | D43: =D24+D32+D41 -> 0
...

Sheet  2
A1: =SOCE!A1 -> L&T ELECTROLYSERS LIMITED
A2: Notes forming part of financial statement
A4: Note 2 - Property, plant and equipment
K6: ='[2]Balance Sheet'!P4 -> ( Amt in Rs.)
A7: Class of asset | B7: Gross Block | F7: Depreciation | J7: Net Block
B8: As at April 01, 2025 | C8: Additions | D8: Deductions | E8: As at March 31, 2026 | F8: =B8 -> As at April 01, 2025 | G8: Additions | H8: Deductions | I8: =E8 -> As at March 31, 2026 | J8: =E8 -> As at March 31, 2026 | K8: As at March 31, 2025
A10: Factory building | B10: 0 | C10: =E10-B10 -> 0 | D10: 0 | F10: 0 | G10: =I10-F10 -> 0 | H10: 0 | J10: =E10+I10 -> 0 | K10: =B10+F10 -> 0
A11: Computers | B11: 0 | C11: =E11-B11 -> 0 | D11: 0 | F11: 0 | G11: =I11-F11 -> 0 | H11: 0 | J11: =E11+I11 -> 0 | K11: =B11+F11 -> 0
A12: Furniture and fixtures | B12: 0 | C12: =E12-B12 -> 0 | D12: 0 | F12: 0 | G12: =I12-F12 -> 0 | H12: 0 | J12: =E12+I12 -> 0 | K12: =B12+F12 -> 0
A13: Plant and machinery | B13: 0 | C13: =E13-B13 -> 0 | D13: 0 | F13: 0 | G13: =I13-F13 -> 0 | H13: 0 | J13: =E13+I13 -> 0 | K13: =B13+F13 -> 0
A14: Electrical installation | B14: 0 | C14: =E14-B14 -> 0 | F14: 0 | G14: =I14-F14 -> 0 | H14: 0 | J14: =E14+I14 -> 0
A15: Office equipment | B15: 0 | C15: =E15-B15 -> 0 | D15: 0 | F15: 0 | G15: =I15-F15 -> 0 | H15: 0 | J15: =E15+I15 -> 0 | K15: =B15+F15 -> 0
A17: Total | B17: =SUM(B10:B15) -> 0 | C17: =SUM(C10:C15) -> 0 | D17: =SUM(D10:D15) -> 0 | E17: =SUM(E10:E15) -> 0 | F17: =SUM(F10:F15) -> 0 | G17: =SUM(G10:G15) -> 0 | H17: =SUM(H10:H15) -> 0 | I17: =SUM(I10:I15) -> 0 | ... K17: =SUM(K10:K15) -> 0
A19: Note 2A - Right of use assets
K20: =K6 -> ( Amt in Rs.)
A21: Class of Asset | B21: Gross Block | F21: Amortization | J21: Net Block
B22: =B8 -> As at April 01, 2025 | C22: Additions | D22: Deductions | E22: =E8 -> As at March 31, 2026 | F22: =B22 -> As at April 01, 2025 | G22: Additions | H22: Deductions | I22: =E22 -> As at March 31, 2026 | J22: =E22 -> As at March 31, 2026 | K22: =K8 -> As at March 31, 2025
A24: Vehicles | B24: =AP20 -> 0 | C24: =E24-B24-D24 -> 0 | D24: 0 | F24: =AP31 -> 0 | G24: =I24-F24-H24 -> 0 | H24: 0 | I24: =AI31 -> 0 | J24: =E24+I24 -> 0 | K24: =B24+F24 -> 0
A25: Land & building | B25: =AP21 -> 0 | C25: =E25-B25 -> 0 | D25: 0 | F25: =AP32 -> 0 | G25: =I25-F25 -> 0 | H25: 0 | I25: =AI32 -> 0 | J25: =E25+I25 -> 0 | K25: =B25+F25 -> 0
A27: Total | B27: =SUM(B23:B26) -> 0 | C27: =SUM(C23:C26) -> 0 | D27: =SUM(D23:D26) -> 0 | E27: =SUM(E23:E26) -> 0 | F27: =SUM(F23:F26) -> 0 | G27: =SUM(G23:G26) -> 0 | H27: =SUM(H23:H26) -> 0 | I27: =SUM(I23:I26) -> 0 | ... K27: =SUM(K23:K26) -> 0
B29: =B17+B27+'3 CWIP'!B13 -> 0

Sheet 3 CWIP
A1: =SOCE!A1 -> L&T ELECTROLYSERS LIMITED
A2: =' 2'!A2 -> Notes forming part of financial statement
A4: Note 3 - Capital work-in-progress
E6: =' 2'!K6 -> ( Amt in Rs.) | F6: ( Amt in Rs.)
A7: Particulars | B7: As at April 01, 2025 | C7: Additions during the year | D7: Deductions | E7: Capitalised assets | F7: As at March 31, 2026
A8: Building | B8: =AP35 -> 0 | C8: =-E8+F8-B8 -> 0 | E8: =-' 2'!C10 -> 0 | F8: =AI35 -> 0
A9: Furniture and fixtures | B9: =AP40 -> 0 | C9: =-E9+F9-B9 -> 0 | E9: =-B9 -> 0 | F9: =AI40 -> 0
A10: Plant and machinery | B10: =AP36 -> 0 | C10: =-E10+F10-B10 -> 0 | D10: 0 | E10: =-(' 2'!C13) -> 0 | F10: =AI36 -> 0
A11: Electrical Installation | B11: =AP37 -> 0 | C11: =-E11+F11-B11 -> 0 | E11: =-' 2'!C14 -> 0 | F11: =AI37 -> 0
A12: Computers | B12: =AP38 -> 0 | E12: =-B12 -> 0 | F12: =AI38 -> 0
A13: Total | B13: =SUM(B8:B12) -> 0 | C13: =SUM(C8:C12) -> 0 | D13: =SUM(D8:D12) -> 0 | E13: =SUM(E8:E12) -> 0 | F13: =SUM(F8:F12) -> 0
A15: Ageing of Capital work in progress:
F16: =E6 -> ( Amt in Rs.)
A17: Particulars | B17: =F7 -> As at March 31, 2026 | F17: Total
B18: Less than 1 year | C18: 1 - 2 years | D18: 2 - 3 years | E18: More than 3 years
A20: Capital work in progress | B20: 0 | C20: =F20-B20 -> 0 | D20: 0 | E20: 0 | F20: =F13 -> 0
A22: Total | B22: =B20 -> 0 | C22: =C20 -> 0 | D22: =D20 -> 0 | E22: =E20 -> 0 | F22: =F20 -> 0
A24: As on the date of the balance sheet, there are no capital work-in-progress projects whose completion is overdue or has exceeded the cost.

Sheet  4
A1: =SOCE!A1 -> L&T ELECTROLYSERS LIMITED
A2: ='3 CWIP'!A2 -> Notes forming part of financial statement
A4: Note 4 - Other intangible assets
K6: ='[2]Balance Sheet'!P4 -> ( Amt in Rs.)
A7: Class of Asset | B7: Gross Block | F7: Depreciation | J7: Net Block
B8: As at April 01, 2025 | C8: Additions | D8: Deductions | E8: =' 2'!E8 -> As at March 31, 2026 | F8: =B8 -> As at April 01, 2025 | G8: Additions | H8: Deductions | I8: =E8 -> As at March 31, 2026 | J8: =E8 -> As at March 31, 2026 | K8: =' 2'!K8 -> As at March 31, 2025
A10: Technical license fees | B10: =AP18 -> 0 | C10: =E10-B10 -> 0 | D10: 0 | E10: =AI18 -> 0 | F10: =AP30 -> 0 | G10: =I10-F10 -> 0 | H10: 0 | I10: =AI30 -> 0 | J10: =E10+I10 -> 0 | K10: =B10+F10 -> 0
A11: Software | B11: =AP17 -> 0 | C11: =E11-B11 -> 0 | D11: 0 | E11: =AI17 -> 0 | F11: =AP29 -> 0 | G11: =I11-F11 -> 0 | H11: 0 | I11: =AI29 -> 0 | J11: =E11+I11 -> 0 | K11: =B11+F11 -> 0
A13: Total | B13: =SUM(B10:B12) -> 0 | C13: =SUM(C10:C12) -> 0 | D13: =SUM(D10:D12) -> 0 | E13: =SUM(E10:E12) -> 0 | F13: =SUM(F10:F12) -> 0 | G13: =SUM(G10:G12) -> 0 | H13: =SUM(H10:H12) -> 0 | I13: =SUM(I10:I12) -> 0 | ... K13: =SUM(K10:K12) -> 0
G15: =' 2'!G27 -> 0

Sheet 5
A1: =SOCE!A1 -> L&T ELECTROLYSERS LIMITED
A2: =' 4'!A2 -> Notes forming part of financial statement
A4: Note 5 - Intangible assets under development
C5: =' 4'!K6 -> ( Amt in Rs.)
A6: Particulars | B6: As at March 31, 2026 | C6: As at March 31, 2025
A8: Carrying value of capital work in progress | B8: =C11 -> 0 | C8: 0
A9: Add:-Capital work in progress during the period | B9: =B11-B8 -> 0 | C9: =AM34 -> 0
A10: Less:- Capitalised assets | B10: 0 | C10: 0
A11: Total | B11: =AF34 -> 0 | C11: =AM34 -> 0
A12: Ageing of Capital work in progress
A14: Particulars | C14: =C6 -> As at March 31, 2025
A16: Project in progress | C16: 0
A17: Less than 1 year | C17: =C9 -> 0
A18: 1-2 years | C18: 0
A19: 2-3 years | C19: 0
A20: More than 3 years | C20: 0
A22: Total | C22: =SUM(C16:C21) -> 0

Sheet 6
A1: =SOCE!A1 -> L&T ELECTROLYSERS LIMITED
A2: ='5'!A2 -> Notes forming part of financial statement
A4: Note 6 - Current assets - Inventories
C5: ='5'!C5 -> ( Amt in Rs.)
A6: Particulars | B6: ='5'!B6 -> As at March 31, 2026 | C6: As at March 31, 2025
A7: Raw material and components
A8: - In stock
A9: - In transit
A10: Stores and spares
A11: Work - in - progress
A12: Finished goods
A14: Total | B14: =SUM(B8:B12) -> 0 | C14: =SUM(C8:C12) -> 0

Sheet 7
A1: =SOCE!A1 -> L&T ELECTROLYSERS LIMITED
A2: ='6'!A2 -> Notes forming part of financial statement
A4: Note 7 - Investment
C5: ='6'!C5 -> ( Amt in Rs.)
A6: Particulars | B6: ='6'!B6 -> As at March 31, 2026 | C6: ='6'!C6 -> As at March 31, 2025
A8: Mutual funds | B8: =SUMIF($K:$K,'7'!$A8,Y:Y) -> 0 | C8: =+AF43+AF42 -> 0
A10: ='6'!A14 -> Total | B10: =SUM(B8:B9) -> 0 | C10: =SUM(C8:C9) -> 0
A12: Details of Mutual funds held:
A14: Particulars | C14: =C6 -> As at March 31, 2025
A16: Nippon India Money Market Fund | C16: 2271953
A17: Aditya Birla Sun Life Money Manager Fund | C17: 232209892
A19: Book value | C19: =C20 -> 0
A20: Market value | C20: =+AF43+AF42 -> 0

Sheet 8
A1: =SOCE!A1 -> L&T ELECTROLYSERS LIMITED
A2: ='7'!A2 -> Notes forming part of financial statement
A4: Note 8 - Current assets - Trade receivable
C5: ='7'!C5 -> ( Amt in Rs.)
A6: Particulars | B6: ='6'!B6 -> As at March 31, 2026 | C6: ='6'!C6 -> As at March 31, 2025
A8: Unsecured: considered good | B8: 0 | C8: 0
A10: ='7'!A10 -> Total | B10: =SUM(B8:B9) -> 0 | C10: =SUM(C8:C9) -> 0

Sheet 9
A1: =SOCE!A1 -> L&T ELECTROLYSERS LIMITED
A2: ='8'!A2 -> Notes forming part of financial statement
A4: Note 9 - Current assets - cash and cash equivalents
C5: ='8'!C5 -> ( Amt in Rs.)
A6: Particulars | B6: ='6'!B6 -> As at March 31, 2026 | C6: ='6'!C6 -> As at March 31, 2025
A7: Balance with banks in current accounts
A9: Fixed deposit with banks (maturity less than 3 months)
A11: ='8'!A10 -> Total | B11: =SUM(B7:B9) -> 0 | C11: =SUM(C7:C9) -> 0

Sheet 10
A1: =SOCE!A1 -> L&T ELECTROLYSERS LIMITED
A2: ='9'!A2 -> Notes forming part of financial statement
A4: Note 10 - Other current financial assets
C5: ='9'!C5 -> ( Amt in Rs.)
A6: Particulars | B6: ='9'!B6 -> As at March 31, 2026 | C6: ='9'!C6 -> As at March 31, 2025
A8: Inter Corporate Deposit
A9: Interest accrued on ICD
A10: Rent deposit
A11: Advance to employees
A13: ='9'!A11 -> Total | B13: =SUM(B8:B11) -> 0 | C13: =SUM(C8:C11) -> 0

Sheet 11
A1: =SOCE!A1 -> L&T ELECTROLYSERS LIMITED
A2: ='9'!A2 -> Notes forming part of financial statement
A4: Note 11 - Other current assets
C5: ='10'!C5 -> ( Amt in Rs.)
A6: Particulars | B6: ='10'!B6 -> As at March 31, 2026 | C6: ='10'!C6 -> As at March 31, 2025
A8: Balance with GST Authorities
A9: L&T Gratuity Trust
A10: Contractual retention money not due
A11: TDS receivable
A12: Prepaid expense
A13: Other receivables
A14: Advance to Suppliers
A15: Interest accrued on FD
A17: ='10'!A13 -> Total | B17: =SUM(B8:B15) -> 0 | C17: =SUM(C8:C15) -> 0
B18: =B17-B14-B10 -> 0

Sheet 12
A1: =SOCE!A1 -> L&T ELECTROLYSERS LIMITED
A2: ='11'!A2 -> Notes forming part of financial statement
A4: Note 12 - Equity share capital
A5: (a) Authorized, issued, subscribed and paid up capital
A6: Particulars | B6: ='11'!B6 -> As at March 31, 2026 | C6: ='11'!C6 -> As at March 31, 2025
A8: Authorized :
A9: ______________ equity shares of Rs 10 each
A12: Issued, subscribed and fully paid up:
A13: Equity shares of Rs 10 each
A14: ( _______________ equity shares of Rs. 10 paid up each fully paid up )
A15: ( Previous year ______________ equity shares of Rs. 10 each fully paid up )
A16: Total | B16: =SUM(B12:B15) -> 0 | C16: =SUM(C12:C15) -> 0
A19: (b) Reconciliation of the number of equity shares and share capital:
A21: Particulars | B21: =B6 -> As at March 31, 2026 | C21: =C6 -> As at March 31, 2025
A22: Equity Shares
A23: Issued, subscribed and fully paid up equity shares at the beginning of the year | B23: =C26 -> 0
A24: Add:
A25: Shares issued during the year | B25: =((B12)/10-B23) -> 0 | C25: =(C12)/10 -> 0
A26: Issued, subscribed and fully paid up equity shares outstanding at the end of the year | B26: =SUM(B22:B25) -> 0 | C26: =SUM(C22:C25) -> 0
A28: Particulars | B28: =B21 -> As at March 31, 2026 | C28: =C21 -> As at March 31, 2025
A29: Equity Share Capital
A30: Issued, subscribed and fully paid up equity shares at the beginning of the year | B30: =B23*10 -> 0 | C30: =C23*10 -> 0
A31: Add:
A32: Share capital issued during the year | B32: =B25*10 -> 0 | C32: =C25*10 -> 0
A33: Issued, subscribed and fully paid up equity share capital outstanding at the end of the year | B33: =SUM(B29:B32) -> 0 | C33: =SUM(C29:C32) -> 0
A35: (i) Terms/rights/restrictions attached to equity shares
A36: (a) The company has only one class of equity shares having a par value of Rs 10 per share. Each holder of equity share is entitled to one vote per share.
A37: (b) All shares issued carry equal rights for dividend declared by the Company. There are no restrictions attached to any specific shareholders.
A38: (c) The Company has not issued any securities during the period with right / option to convert the same into equity shares at a later date.
A40: (ii) Details of equity shares held by the Holding Company
A41: Particulars | B41: =B6 -> As at March 31, 2026 | C41: =C6 -> As at March 31, 2025
A43: L&T Energy Green Tech Limited | B43: =B12/10 -> 0 | C43: =C12/10 -> 0
A45: (iii) Details of share holders holding more than 5% of the Company
A46: Particulars | B46: =B6 -> As at March 31, 2026 | C46: =C6 -> As at March 31, 2025
A48: L&T Energy Green Tech Limited (100% holding) (No. of shares) | B48: =B43 -> 0 | C48: =C43 -> 0
A50: (iv) Details of promoters share holding
A51: Particulars | B51: =B46 -> As at March 31, 2026 | C51: =C46 -> As at March 31, 2025
A53: L&T Energy Green Tech Limited (100% holding) (No. of shares) | B53: =B48 -> 0 | C53: =C48 -> 0

Sheet 13
A1: =SOCE!A1 -> L&T ELECTROLYSERS LIMITED
A2: ='12'!A2 -> Notes forming part of financial statement
A4: Note 13 - Other equity
E5: ='11'!C5 -> ( Amt in Rs.)
A6: Particulars | B6: Equity Share Capital | C6: Other Equity
C7: Retained earnings | D7: Items of other comprehensive income | E7: Total Other equity
A8: Balance as on 1 April 2025 (A) | B8: =B26 -> 0 | C8: =C26 -> 0 | D8: =D26 -> 0 | E8: =E26 -> 0
A9: Shares Issued during the year (B) | B9: ='12'!B32 -> 0
A10: Profit/ (loss) for the year | C10: =SOCE!F33 -> 0 | E10: =SUM(C10:D10) -> 0
A11: Other comprehesive income (loss) for the year
A12: - Remeasurement gain (loss) for the year | D12: =SOCE!D36 -> 0 | E12: =SUM(C12:D12) -> 0
A13: Total comprehesive income (loss) for the year (B) | C13: =SUM(C10:C12) -> 0 | D13: =SUM(D10:D12) -> 0 | E13: =SUM(C13:D13) -> 0
A14: Balance as on 31 March 2026 (C.) | B14: =SUM(B8:B13) -> 0 | C14: =C8+C13 -> 0 | D14: =D8+D13 -> 0 | E14: =E8+E13 -> 0
E17: =E5 -> ( Amt in Rs.)
A18: Particulars | B18: Equity Share Capital | C18: Other Equity
C19: Retained earnings | D19: Items of other comprehensive income | E19: Total Other equity
A20: Balance as on 1 April 2024 (A) | B20: ='12'!C30 -> 0 | C20: =SOCE!F43 -> 0 | D20: =SOCE!D43 -> 0 | E20: 0
A21: Shares Issued during the year (B) | B21: ='12'!C32 -> 0
A22: Profit/ (loss) for the year | C22: =SOCE!F44 -> 0 | E22: =SUM(C22:D22) -> 0
A23: Other comprehesive income (loss) for the year
A24: - Remeasurement gain (loss) for the year | D24: =SOCE!D47 -> 0 | E24: =SUM(C24:D24) -> 0
A25: Total comprehesive income (loss) for the year (C) | C25: =SUM(C22:C24) -> 0 | D25: =SUM(D22:D24) -> 0 | E25: =SUM(E22:E24) -> 0
A26: Balance as on 31 March 2025 (D) | B26: =SUM(B20:B25) -> 0 | C26: =C20+C25 -> 0 | D26: =D20+D25 -> 0 | E26: =E20+E25 -> 0

Sheet 14
A1: =SOCE!A1 -> L&T ELECTROLYSERS LIMITED
A2: =[1]xx13!A2 -> Notes forming part of financial statement
A4: Note 14 - Current liabilities - borrowings
C5: =[1]xx13!L5 -> ( Amt in Rs.)
A6: Particulars | B6: =[1]xx13!H6 -> As at March 31, 2026 | C6: ='12'!C41 -> As at March 31, 2025
A8: Unsecured loan
A9: Working capital facilities
A10: Interest accured but not due
A12: Total | B12: =SUM(B8:B10) -> 0 | C12: =SUM(C8:C10) -> 0
A14: Note: The Company has been sanctioned working capital limits in excess of five crore rupees, in aggregate from the bank during the
A15: year on the basis of security of current assets. The filing of quarterly returns or statements have not been requested by the bank from
A16: the Company for the working capital facilities granted during previous year.

Sheet 15
A1: =SOCE!A1 -> L&T ELECTROLYSERS LIMITED
A2: ='14'!A2 -> Notes forming part of financial statement
A4: Note 15 - Current liabilities - trade payables
C5: ='14'!C5 -> ( Amt in Rs.)
A6: Particulars | B6: ='14'!B6 -> As at March 31, 2026 | C6: ='14'!C6 -> As at March 31, 2025
A8: Due to:
A9: - Micro, Small and Medium Enterprise
A10: - Others
A12: ='14'!A12 -> Total | B12: =SUM(B8:B10) -> 0 | C12: =SUM(C8:C10) -> 0
A14: For Trade payable ageing, refer note 15(a)
A16: Disclosure Pursuant to Micro Small and Medium Enterprises Development Act, 2006 (MSMED Act).
A18: Particulars | B18: =B6 -> As at March 31, 2026 | C18: =C6 -> As at March 31, 2025
A20: Amount due to suppliers under MSMED Act, 2006 | B20: 0 | C20: 0
A21: Amount not due to suppliers under MSMED Act, 2006 | B21: 0 | C21: 0
A22: Interst accrued and remaning unpaid at the end of the period to suppliers under MSMED Act | B22: =C22 -> 0 | C22: 0
A23: Total | B23: =SUM(B20:B22) -> 0 | C23: =SUM(C20:C22) -> 0

Sheet 15a
A1: =SOCE!A1 -> L&T ELECTROLYSERS LIMITED
A2: Notes forming part of balance sheet
A4: Note - [15](a)
A5: Trade payable ageing
A7: As at March 31, 2026 | G7: ='[3]15'!I6 -> ( Amt in Rs.)
A8: Particulars | B8: Outstanding for the following periods from the due date of payment | G8: Total
B9: Not due | C9: Less than 1 year | D9: 1-2 years | E9: 2-3 years | F9: More than 3 years
A11: Undisputed
A12: - Micro and Small enterprise | B12: ='15'!B21 -> 0 | C12: =G12-B12-D12 -> 0 | D12: ='15'!B22 -> 0 | E12: 0 | F12: 0 | G12: ='15'!B23 -> 0
A13: - Others | B13: 0 | C13: 0 | D13: =G13-C13-B13-E13 -> 0 | E13: 0 | F13: 0 | G13: ='15'!B10 -> 0
A15: Disputed
A16: - Micro and Small enterprise | B16: 0 | C16: 0 | D16: 0 | E16: 0 | F16: 0 | G16: =SUM(B16:F16) -> 0
A17: - Others | B17: 0 | C17: 0 | D17: 0 | E17: 0 | F17: 0 | G17: =SUM(B17:F17) -> 0
A19: Total | B19: =SUM(B12:B17) -> 0 | C19: =SUM(C12:C17) -> 0 | D19: =SUM(D12:D17) -> 0 | E19: =SUM(E12:E17) -> 0 | F19: =SUM(F12:F17) -> 0 | G19: =SUM(G12:G17) -> 0 | I19: =BS!G43-G19 -> 0
A21: As at March 31, 2025 | G21: ='[3]15'!I6 -> ( Amt in Rs.)
A22: Particulars | B22: Outstanding for the following periods from the due date of payment | G22: Total
B23: Not due | C23: Less than 1 year | D23: 1-2 years | E23: 2-3 years | F23: More than 3 years
A25: Undisputed
A26: - Micro and Small enterprise | B26: 0 | C26: 0 | D26: 0 | E26: 0 | F26: 0 | G26: =SUM(B26:F26) -> 0
A27: - Others | B27: 0 | C27: 0 | D27: 0 | E27: 0 | F27: 0 | G27: =SUM(B27:F27) -> 0
A29: Disputed
A30: - Micro and Small enterprise | B30: 0 | C30: 0 | D30: 0 | E30: 0 | F30: 0 | G30: =SUM(B30:F30) -> 0
A31: - Others | B31: 0 | C31: 0 | D31: 0 | E31: 0 | F31: 0 | G31: =SUM(B31:F31) -> 0
A33: Total | B33: =SUM(B26:B31) -> 0 | C33: =SUM(C26:C31) -> 0 | D33: =SUM(D26:D31) -> 0 | E33: =SUM(E26:E31) -> 0 | F33: =SUM(F26:F31) -> 0 | G33: =SUM(G26:G31) -> 0

Sheet 16
A1: =SOCE!A1 -> L&T ELECTROLYSERS LIMITED
A2: ='15'!A2 -> Notes forming part of financial statement
A4: Note 16 - Current liabilities - other financial liabilities
C5: ='15'!C5 -> ( Amt in Rs.)
A6: Particulars | B6: ='15'!B6 -> As at March 31, 2026 | C6: ='15'!C6 -> As at March 31, 2025
A8: Due to holding company
A9: Liabilities towards employees/ workmen
A10: Due to ultimate holding company
A11: Other payables
A13: ='15'!A12 -> Total | B13: =SUM(B8:B11) -> 0 | C13: =SUM(C8:C11) -> 0

Sheet 17
A1: =SOCE!A1 -> L&T ELECTROLYSERS LIMITED
A2: ='15'!A2 -> Notes forming part of financial statement
A4: Note 17 - Current liabilities - other current liabilities
C5: ='16'!C5 -> ( Amt in Rs.)
A6: Particulars | B6: ='15'!B6 -> As at March 31, 2026 | C6: ='15'!C6 -> As at March 31, 2025
A8: Statutory payables:
A9: TCS Payable
A10: TDS Payable
A11: Goods and Services tax payable
A13: Provisions related to employee benefits:
A14: Gratuity payable
A16: Customer advances
A17: Other provisions
A19: ='16'!A13 -> Total | B19: =SUM(B9:B17) -> 0 | C19: =SUM(C10:C17) -> 0

Sheet 18
A1: =SOCE!A1 -> L&T ELECTROLYSERS LIMITED
A2: ='15'!A2 -> Notes forming part of financial statement
A4: Note 18 - Current liabilities - provisions
C5: ='17'!C5 -> ( Amt in Rs.)
A6: Particulars | B6: ='17'!B6 -> As at March 31, 2026 | C6: ='15'!C6 -> As at March 31, 2025
A8: Provisions related to employee benefits
A9: Compensated absences
A10: Other provisions
A12: ='17'!A19 -> Total | B12: =SUM(B8:B10) -> 0 | C12: =SUM(C8:C10) -> 0
B14: =B9-C9 -> 0

Sheet 19
A1: =SOCE!A1 -> L&T ELECTROLYSERS LIMITED
A2: ='18'!A2 -> Notes forming part of financial statement
A4: Note 19 - Revenue from operations
C5: ='18'!C5 -> ( Amt in Rs.)
A6: Particulars | B6: For the year ended March 31, 2026 | C6: For the year ended March 31, 2025
A8: Sale of goods - Domestic
A10: ='18'!A12 -> Total | B10: =SUM(B8:B9) -> 0 | C10: =SUM(C8:C9) -> 0

Sheet 20
A1: =SOCE!A1 -> L&T ELECTROLYSERS LIMITED
A2: ='18'!A2 -> Notes forming part of financial statement
A4: Note 20 - Other income
C5: ='19'!C5 -> ( Amt in Rs.)
A6: Particulars | B6: ='19'!B6 -> For the year ended March 31, 2026 | C6: ='19'!C6 -> For the year ended March 31, 2025
A8: Interest on Inter corporate deposit
A9: Gain on sale of investment
A10: Scrap Sale
A11: Interest on fixed deposit
A12: Gain on de-recognition of lease liability/ROU
A13: Interest on income tax refund
A15: ='19'!A10 -> Total | B15: =SUM(B8:B13) -> 0 | C15: =SUM(C8:C13) -> 0
A18: Interest on Inter corporate deposit | B18: =B8 -> 0
A19: Interest on fixed deposit | B19: =B11 -> 0
A20: Interest on income tax refund | B20: =B13 -> 0

Sheet 21
A1: =SOCE!A1 -> L&T ELECTROLYSERS LIMITED
A2: ='20'!A2 -> Notes forming part of financial statement
A4: Note 21 (a) - Cost of raw materials and components consumed
C5: ='20'!C5 -> ( Amt in Rs.)
A6: Particulars | B6: ='20'!B6 -> For the year ended March 31, 2026 | C6: ='20'!C6 -> For the year ended March 31, 2025
A7: Auditor Remmunration
A8: Bank Charges
A9: Fees & Taxes
A11: Purchases of raw materials
A12: Provision for slow moving inventory
A13: Components consumed
A14: Cost of goods manufactured
A15: Freight inwards
A16: Stores and consumables
A17: Transfer to closing inventory
A18: ='20'!A15 -> Total | B18: =SUM(B7:B17) -> 0 | C18: =SUM(C7:C17) -> 0
A20: Note 21 (b) - Manufacturing and other operating expenses
A22: Particulars | B22: =B6 -> For the year ended March 31, 2026 | C22: =C6 -> For the year ended March 31, 2025
A24: Facility charges
A25: Subcontractor charges
A26: Professional fees
A27: Testing and inspection charges
A28: Other manufacturing expenses
A29: Royalty and technical knowhow
A30: Insurance
A31: Repairs and maintenance
A32: Subscription charges
A33: =A18 -> Total | B33: =SUM(B24:B32) -> 0 | C33: =SUM(C24:C32) -> 0
A35: Note 21 (c) - Change in inventories of finished goods and work-in-progress
A37: Particulars | B37: =B22 -> For the year ended March 31, 2026 | C37: =C22 -> For the year ended March 31, 2025
A39: Opening balance
A40: Raw materials
A41: Work - in - progress
A42: Finished goods
A43: Opening balance | B43: =SUM(B40:B42) -> 0 | C43: =SUM(C40:C42) -> 0
A45: Closing balance
A46: Raw materials
A47: Work - in - progress
A48: Finished goods
A49: Closing balance | B49: =SUM(B46:B48) -> 0 | C49: =SUM(C46:C48) -> 0
...

Sheet 22
A1: =SOCE!A1 -> L&T ELECTROLYSERS LIMITED
A2: ='23'!A2 -> Notes forming part of financial statement
A4: Note 22 - Employee benefit expenses
C5: ='21'!C5 -> ( Amt in Rs.)
A6: Particulars | B6: ='20'!B6 -> For the year ended March 31, 2026 | C6: ='20'!C6 -> For the year ended March 31, 2025
A8: Salaries, wages and bonus
A9: Contribution to PF and other funds
A10: Gratuity and leave encashment
A11: Staff welfare expenses
A13: ='21'!A18 -> Total | B13: =SUM(B8:B11) -> 0 | C13: =SUM(C8:C11) -> 0
A15: Note 22 A - Exceptional Item (employee benefits)
C16: =C5 -> ( Amt in Rs.)
A17: Particulars | B17: =B6 -> For the year ended March 31, 2026 | C17: =C6 -> For the year ended March 31, 2025
A19: Past service cost* | B19: 0 | C19: 0
A21: Total | B21: =SUM(B19:B19) -> 0 | C21: =SUM(C19:C19) -> 0
A23: *Additional gratuity liability for the past service of the employees due to new wage code.
A27: Flexi Balance
A28: Retention Pay
A29: Basic Salary
A30: Deputation Charges
A31: Variable remuneration
A32: PLR S & Employees
A33: HRA - Sup & above
A34: Leave Encash. Paid
A35: Training - In house
A36: Training - External
A37: Mileage - Owned Car
... A61: Gift Articles
A62: Total | C62: =SUM(C27:C61) -> 0

Sheet 23
A1: =SOCE!A1 -> L&T ELECTROLYSERS LIMITED
A2: ='21'!A2 -> Notes forming part of financial statement
A4: Note 23 - Selling, administration and other expenses
C5: ='22'!C5 -> ( Amt in Rs.)
A6: Particulars | B6: ='22'!B6 -> For the year ended March 31, 2026 | C6: ='22'!C6 -> For the year ended March 31, 2025
A8: Facility charge
A9: Travel & conveyance
A10: Overheads charges by holding company
A11: Management consultancy and professional fees
A12: Rent and brokerage
A13: General repairs & maintenance
A14: Foreign exchange fluctuation (Gain)/loss
A15: Miscellaneous expense
A16: House keeping charges
A17: Bank guarantee charges
A18: Health, safety and environment expense
A19: Advertising
... A27: Insurance expense
A29: Total | B29: =SUM(B7:B28) -> 0 | C29: =SUM(C8:C27) -> 0
A32: Rates & Taxes-Others
A33: Freight forwarding
A34: Tele. Installations
A35: Courier Charges
A36: Books & Periodicals
A37: Computer Hire Charg.
A38: Subscription Others
A39: Sundry Expenses
A40: Office Running Exp
A41: Donations
A44: Computer software
A45: House keeping charges
... A51: Foreign exchange fluctuation (Gain)/loss

Sheet 24
A1: =SOCE!A1 -> L&T ELECTROLYSERS LIMITED
A2: ='25'!A2 -> Notes forming part of financial statement
A4: Note 24 - Finance cost
C5: ='23'!C5 -> ( Amt in Rs.)
A6: Particulars | B6: ='23'!B6 -> For the year ended March 31, 2026 | C6: ='23'!C6 -> For the year ended March 31, 2025
A8: Interest on borrowing
A9: Interest on MSME
A10: Interest on lease liability
A11: Interest cost- Gratuity
A12: Interest on custom duty and TDS
A14: ='23'!A29 -> Total | B14: =SUM(B8:B12) -> 0 | C14: =SUM(C8:C12) -> 0

Sheet 25
A1: =SOCE!A1 -> L&T ELECTROLYSERS LIMITED
A2: ='22'!A2 -> Notes forming part of financial statement
A4: Note 25 - Depreciation and amortisation
C5: ='24'!C5 -> ( Amt in Rs.)
A6: Particulars | B6: ='24'!B6 -> For the year ended March 31, 2026 | C6: ='24'!C6 -> For the year ended March 31, 2025
A8: Depreciation on tangible assets
A9: Amortisation of intangible assets
A10: Obsolescence of fixed assets
A12: ='24'!A14 -> Total | B12: =SUM(B8:B10) -> 0 | C12: =SUM(C8:C9) -> 0

Sheet 26
A1: =SOCE!A1 -> L&T ELECTROLYSERS LIMITED
A2: ='22'!A2 -> Notes forming part of financial statement
A4: Note 26 - Earnings per equity share(basic and diluted)
A7: Particulars | B7: For the year ended March 31, 2026 | C7: ='25'!C6 -> For the year ended March 31, 2025
A8: Basic & Diluted Earnings per share
A9: Net profit after tax | B9: =PL!E32 -> 0 | C9: =PL!G27 -> 0
A10: Weighted average number of equity shares outstanding | B10: =I38 -> 0 | C10: =I51 -> 0
A11: Basic EPS | B11: =B9/B10 -> #DIV/0! | C11: =C9/C10 -> #DIV/0!
A13: Face value per share | B13: =C13 -> 10 | C13: 10

Sheet 27 Ratios
A1: =SOCE!A1 -> L&T ELECTROLYSERS LIMITED
A2: ='22'!A2 -> Notes forming part of financial statement
A4: Note 27
A5: Following are the analytical ratios for the year ended March 31, 2026 and March 31, 2025
A7: Ratio | B7: Numerator | C7: Denominator | D7: Numerator | E7: Denominator | F7: As at Mar 31, 2026 | G7: Numerator | H7: Denominator | I7: As at Mar 31, 2025 | J7: Variance % | K7: Reason of variance [for change more than 25%]
A8: Current Ratio (times) | B8: Current asset | C8: Current liabilities | D8: =BS!F25 -> 0 | E8: =BS!F47 -> 0 | F8: =D8/E8 -> #DIV/0! | I8: =G8/H8 -> #DIV/0! | J8: =(I8-F8)/I8 -> #DIV/0!
A10: Debt Equity Ratio (times) | B10: Total Debt | C10: Shareholder's Equity | D10: =BS!E41 -> 0 | E10: =BS!E31 -> 0 | F10: =D10/E10 -> #DIV/0! | I10: =G10/H10 -> #DIV/0! | J10: =(I10-F10)/I10 -> #DIV/0!
A12: Debt Service Coverage Ratio (times) | B12: Earnings available for debt service | C12: Debt Service | D12: =D26 -> 0 | E12: =BS!E41 -> 0 | F12: =D12/E12 -> #DIV/0! | I12: =G12/H12 -> #DIV/0! | J12: =(I12-F12)/I12 -> #DIV/0!
A14: Return on Equity (%) | B14: Profit for the year after tax | C14: Average shareholders equity | D14: =PL!E27 -> 0 | E14: =(BS!F33+BS!H33)/2 -> 0 | F14: =D14/E14 -> #DIV/0! | I14: =G14/H14 -> #DIV/0! | J14: =(I14-F14)/I14 -> #DIV/0!
A16: Inventory turnover Ratio | B16: COGS | C16: Average inventory | D16: =(#REF!+#REF!) -> #REF! | E16: =(BS!E18+BS!G18)/2 -> 0 | F16: =D16/E16 -> #REF! | I16: =G16/H16 -> #DIV/0! | J16: =(I16-F16)/I16 -> #DIV/0!
A18: Trade receivable turnover Ratio | B18: Revenue from operations | C18: Average Gross Trade Receivables | D18: =PL!E6 -> 0 | E18: =(BS!E21+BS!G21)/2 -> 0 | F18: =D18/E18 -> #DIV/0! | I18: =G18/H18 -> #DIV/0! | J18: =(I18-F18)/I18 -> #DIV/0!
A20: Trade payable turnover Ratio | B20: Purchases | C20: Average Trade Payables | D20: =SUM('21'!B18) -> 0 | E20: =(BS!E43+BS!G43)/2 -> 0 | F20: =D20/E20 -> #DIV/0! | I20: =G20/H20 -> #DIV/0! | J20: =(I20-F20)/I20 -> #DIV/0!
A22: Net capital turnover Ratio | B22: =B18 -> Revenue from operations | C22: Average Working Capital | D22: =D18 -> 0 | E22: =((BS!E18+BS!E21+BS!E23+BS!E24-BS!E43-BS!E45)+(BS!G18+BS!G21+BS!G24-BS!G43-BS!G45))/2 -> 0 | F22: =D22/E22 -> #DIV/0! | I22: =G22/H22 -> #DIV/0! | J22: =(I22-F22)/I22 -> #DIV/0!
A24: Net profit Ratio (%) | B24: Profit for the year after tax | C24: Revenue from operations | D24: =D14 -> 0 | E24: =D22 -> 0 | F24: =D24/E24 -> #DIV/0! | I24: =G24/H24 -> #DIV/0! | J24: =(I24-F24)/I24 -> #DIV/0!
A26: ROCE (%) | B26: Profit after tax + Finance Cost | C26: Average Capital Employed | D26: =PL!E27+PL!E16 -> 0 | E26: =(BS!F33+BS!H33)/2 -> 0 | F26: =D26/E26 -> #DIV/0! | I26: =G26/H26 -> #DIV/0! | J26: =(I26-F26)/I26 -> #DIV/0!

Sheet Note 28 to 43
A1: Notes forming part of Accounts
B2: 28 | C2: Commitment and leases
C3: Capital commitment
D4: Capital expenditure contracted for at the end of the reporting period but not recognized as liabilities is as follows:
G5: =G67 -> ( Amount in ₹ )
D6: Sr no. | E6: Particulars | F6: As at March 31, 2026 | G6: As at March 31, 2025
D7: 1 | E7: Property, plant and equipment | F7: 0 | G7: 0
D8: 2 | E8: Intangible asset | F8: 0 | G8: 0
C10: Lease
C11: The Company has taken various commercial premises and plant and equipment under cancellable operating leases. The leases have varying terms, escalation clauses and renewal rights. On renewal, the terms of the leases are renegotiated. Lease rental expenses charged to statement of profit and loss is ₹ 6.87 crores
C12: Contingent rent recognized in statement of Profit and loss is ₹ Nil
B14: =B2+1 -> 29 | C14: Auditors remuneration | G14: =G5 -> ( Amount in ₹ )
D15: Sr no. | E15: Particulars | F15: =F6 -> As at March 31, 2026 | G15: =G6 -> As at March 31, 2025
D16: 1 | E16: Statutory audit | F16: 0 | G16: 0
D17: =D16+1 -> 2 | E17: Limited review fees | F17: 0 | G17: 0
D18: =D17+1 -> 3 | E18: Transfer pricing audit | F18: 0 | G18: 0
D19: =D18+1 -> 4 | E19: Certification Fees | F19: 0 | G19: 0
D20: =D19+1 -> 5 | E20: Reimbursement | F20: 0 | G20: 0
E21: Total | F21: =SUM(F16:F20) -> 0 | G21: =SUM(G16:G20) -> 0
B24: =B14+1 -> 30 | C24: Disclosure pursuant to Accounting Standard (Ind AS) 19 Employee Benefits:
D25: a. Defined contribution plan
D26: Compensated absences
D27: Amount of ₹ ________ is recognised as an expense and included in "Employee benefits expense" [Note 22] in the statement of profit or loss.
D29: b. Defined benefit plans
D30: Gratuity
D31: The component of the defined benefit obligation which is attributable to future salary increases is shown in the table below:
G33: =G14 -> ( Amount in ₹ )
D34: Particulars | F34: Year ended March 31, 2026 | G34: Year ended March 31, 2025
D35: Defined benefit obligation without effect of projected salary growth | F35: 0 | G35: 0
D36: Plus effect of salary growth | F36: 0 | G36: 0
D37: Defined benefit obligation with projected salary growth | F37: =SUM(F35:F36) -> 0 | G37: =SUM(G35:G36) -> 0
D39: Amount recorded in other comprehensive income
D40: The total amount of remeasurement items and impact of liabilities assumed or settled, if any, which is recorded immediately in Other Comprehensive Income (OCI) during the period is shown in the table below:
G41: =G33 -> ( Amount in ₹ )
D42: Particulars | F42: =F15 -> As at March 31, 2026 | G42: =G15 -> As at March 31, 2025
D43: Opening amounts recognised outside profit and loss | F43: =G50 -> 0 | G43: 0
D44: Remeasurements during the period due to
D45: Changes in financial assumptions | F45: 0 | G45: 0
D46: Changes in demographic assumptions
D47: Experience adjustments | F47: 0 | G47: 0
...
